Workbook

Sheet MinorData
A1: Direction | B1: Export | C1: Export | D1: Export | E1: Export | F1: Export | G1: Export | H1: Export | I1: Export | J1: Export | K1: Export | L1: Export | M1: Export | N1: Export | O1: Export | P1: Export | Q1: Export | R1: Export | S1: Export | T1: Export | U1: Export | V1: Export | W1: Export | X1: Export | Y1: Export | Z1: Export | AA1: Export | AB1: Export | AC1: Export | AD1: Export | AE1: Export | AF1: Export | AG1: Export | AH1: Export | AI1: Export | AJ1: Export | AK1: Export | AL1: Export | AM1: Export | AN1: Export | AO1: Export | AP1: Export | AQ1: Export | AR1: Export | AS1: Export | AT1: Export | AU1: Export | AV1: Export | AW1: Export | AX1: Export | AY1: Export | AZ1: Export | BA1: Export | BB1: Import | BC1: Import | BD1: Import | BE1: Import | BF1: Import | BG1: Import | BH1: Import | BI1: Import | BJ1: Import | BK1: Import | BL1: Import | BM1: Import | BN1: Import | BO1: Import | BP1: Import | BQ1: Import | BR1: Import | BS1: Import | BT1: Import | BU1: Import | BV1: Import | BW1: Import | BX1: Import | BY1: Import | BZ1: Import | CA1: Import | CB1: Import | CC1: Import | CD1: Import | CE1: Import | CF1: Import | CG1: Import | CH1: Import | CI1: Import | CJ1: Import | CK1: Import | CL1: Import | CM1: Import | CN1: Import | CO1: Import | CP1: Import | CQ1: Import | CR1: Import | CS1: Import | CT1: Import | CU1: Import | CV1: Import | CW1: Import | CX1: Import | CY1: Import | CZ1: Import | DA1: Import | DB1: Import | DC1: Import | DD1: Import | DE1: Import | DF1: Import | DG1: Import | DH1: Import | DI1: Import | DJ1: Export | DK1: Export | DL1: Export | DM1: Export | DN1: Export | DO1: Export | DP1: Export | DQ1: Export | DR1: Export | DS1: Export | DT1: Export | DU1: Export | DV1: Export | DW1: Export | DX1: Export | DY1: Export | DZ1: Export | EA1: Export | EB1: Export | EC1: Export | ED1: Export | EE1: Export | EF1: Export | EG1: Export | EH1: Export | EI1: Export | EJ1: Import | EK1: Import | EL1: Import | EM1: Import | EN1: Import | EO1: Import | EP1: Import | EQ1: Import | ER1: Import | ES1: Import | ET1: Import | EU1: Import | EV1: Import | EW1: Import | EX1: Import | EY1: Import | EZ1: Import | FA1: Import | FB1: Import | FC1: Import | FD1: Import | FE1: Import | FF1: Import | FG1: Import | FH1: Import | FI1: Import | FJ1: Import | FK1: Import | FL1: Import | FM1: Import
A2: Data Type | B2: Price Index | C2: Price Index | D2: Price Index | E2: Price Index | F2: Price Index | G2: Price Index | H2: Price Index | I2: Price Index | J2: Price Index | K2: Price Index | L2: Price Index | M2: Price Index | N2: Price Index | O2: Price Index | P2: Price Index | Q2: Price Index | R2: Price Index | S2: Price Index | T2: Price Index | U2: Price Index | V2: Price Index | W2: Price Index | X2: Price Index | Y2: Price Index | Z2: Price Index | AA2: Price Index | AB2: Quantity Index | AC2: Quantity Index | AD2: Quantity Index | AE2: Quantity Index | AF2: Quantity Index | AG2: Quantity Index | AH2: Quantity Index | AI2: Quantity Index | AJ2: Quantity Index | AK2: Quantity Index | AL2: Quantity Index | AM2: Quantity Index | AN2: Quantity Index | AO2: Quantity Index | AP2: Quantity Index | AQ2: Quantity Index | AR2: Quantity Index | AS2: Quantity Index | AT2: Quantity Index | AU2: Quantity Index | AV2: Quantity Index | AW2: Quantity Index | AX2: Quantity Index | AY2: Quantity Index | AZ2: Quantity Index | BA2: Quantity Index | BB2: Price Index | BC2: Price Index | BD2: Price Index | BE2: Price Index | BF2: Price Index | BG2: Price Index | BH2: Price Index | BI2: Price Index | BJ2: Price Index | BK2: Price Index | BL2: Price Index | BM2: Price Index | BN2: Price Index | BO2: Price Index | BP2: Price Index | BQ2: Price Index | BR2: Price Index | BS2: Price Index | BT2: Price Index | BU2: Price Index | BV2: Price Index | BW2: Price Index | BX2: Price Index | BY2: Price Index | BZ2: Price Index | CA2: Price Index | CB2: Price Index | CC2: Price Index | CD2: Price Index | CE2: Price Index | CF2: Quantity Index | CG2: Quantity Index | CH2: Quantity Index | CI2: Quantity Index | CJ2: Quantity Index | CK2: Quantity Index | CL2: Quantity Index | CM2: Quantity Index | CN2: Quantity Index | CO2: Quantity Index | CP2: Quantity Index | CQ2: Quantity Index | CR2: Quantity Index | CS2: Quantity Index | CT2: Quantity Index | CU2: Quantity Index | CV2: Quantity Index | CW2: Quantity Index | CX2: Quantity Index | CY2: Quantity Index | CZ2: Quantity Index | DA2: Quantity Index | DB2: Quantity Index | DC2: Quantity Index | DD2: Quantity Index | DE2: Quantity Index | DF2: Quantity Index | DG2: Quantity Index | DH2: Quantity Index | DI2: Quantity Index | DJ2: $mn | DK2: $mn | DL2: $mn | DM2: $mn | DN2: $mn | DO2: $mn | DP2: $mn | DQ2: $mn | DR2: $mn | DS2: $mn | DT2: $mn | DU2: $mn | DV2: $mn | DW2: $mn | DX2: $mn | DY2: $mn | DZ2: $mn | EA2: $mn | EB2: $mn | EC2: $mn | ED2: $mn | EE2: $mn | EF2: $mn | EG2: $mn | EH2: $mn | EI2: $mn | EJ2: $mn | EK2: $mn | EL2: $mn | EM2: $mn | EN2: $mn | EO2: $mn | EP2: $mn | EQ2: $mn | ER2: $mn | ES2: $mn | ET2: $mn | EU2: $mn | EV2: $mn | EW2: $mn | EX2: $mn | EY2: $mn | EZ2: $mn | FA2: $mn | FB2: $mn | FC2: $mn | FD2: $mn | FE2: $mn | FF2: $mn | FG2: $mn | FH2: $mn | FI2: $mn | FJ2: $mn | FK2: $mn | FL2: $mn | FM2: $mn
A3: Good Name | B3: =IF(B$1="Export",INDEX(CodesIndex!$B$3:$B$200,MATCH(B$4,CodesIndex!$A$3:$A$200,0)),IF(B1="Import",INDEX(CodesIndex!$D$3:$D$200,MATCH(B$4,CodesIndex!$C$3:$C$200,0)),NA())) -> Crude animal foods, agricultural | C3: =IF(C$1="Export",INDEX(CodesIndex!$B$3:$B$200,MATCH(C$4,CodesIndex!$A$3:$A$200,0)),IF(C1="Import",INDEX(CodesIndex!$D$3:$D$200,MATCH(C$4,CodesIndex!$C$3:$C$200,0)),NA())) -> Grains | D3: =IF(D$1="Export",INDEX(CodesIndex!$B$3:$B$200,MATCH(D$4,CodesIndex!$A$3:$A$200,0)),IF(D1="Import",INDEX(CodesIndex!$D$3:$D$200,MATCH(D$4,CodesIndex!$C$3:$C$200,0)),NA())) -> Beef | E3: =IF(E$1="Export",INDEX(CodesIndex!$B$3:$B$200,MATCH(E$4,CodesIndex!$A$3:$A$200,0)),IF(E1="Import",INDEX(CodesIndex!$D$3:$D$200,MATCH(E$4,CodesIndex!$C$3:$C$200,0)),NA())) -> Pork and related products | F3: =IF(F$1="Export",INDEX(CodesIndex!$B$3:$B$200,MATCH(F$4,CodesIndex!$A$3:$A$200,0)),IF(F1="Import",INDEX(CodesIndex!$D$3:$D$200,MATCH(F$4,CodesIndex!$C$3:$C$200,0)),NA())) -> Lard, oleo, and related products | G3: =IF(G$1="Export",INDEX(CodesIndex!$B$3:$B$200,MATCH(G$4,CodesIndex!$A$3:$A$200,0)),IF(G1="Import",INDEX(CodesIndex!$D$3:$D$200,MATCH(G$4,CodesIndex!$C$3:$C$200,0)),NA())) -> Dairy products, manufactured | H3: =IF(H$1="Export",INDEX(CodesIndex!$B$3:$B$200,MATCH(H$4,CodesIndex!$A$3:$A$200,0)),IF(H1="Import",INDEX(CodesIndex!$D$3:$D$200,MATCH(H$4,CodesIndex!$C$3:$C$200,0)),NA())) -> Flour and other grain products | I3: =IF(I$1="Export",INDEX(CodesIndex!$B$3:$B$200,MATCH(I$4,CodesIndex!$A$3:$A$200,0)),IF(I1="Import",INDEX(CodesIndex!$D$3:$D$200,MATCH(I$4,CodesIndex!$C$3:$C$200,0)),NA())) -> Vegetable oil, cake, and meal | ... FM3: =IF(FM$1="Export",INDEX(CodesIndex!$B$3:$B$200,MATCH(FM$4,CodesIndex!$A$3:$A$200,0)),IF(FM1="Import",INDEX(CodesIndex!$D$3:$D$200,MATCH(FM$4,CodesIndex!$C$3:$C$200,0)),NA())) -> Chemicals, semimanufactured
A4: Good # | B4: 1 | C4: 5 | D4: 8 | E4: 9 | F4: 11 | G4: 12 | H4: 14 | I4: 15 | J4: 25 | K4: 28 | L4: 42 | M4: 44 | N4: 52 | O4: 55 | P4: 57 | Q4: 59 | R4: 60 | S4: 61 | T4: 66 | U4: 67 | V4: 69 | W4: 70 | X4: 71 | Y4: 72 | Z4: 74 | AA4: 75 | AB4: 1 | AC4: 5 | AD4: 8 | AE4: 9 | AF4: 11 | AG4: 12 | AH4: 14 | AI4: 15 | AJ4: 25 | AK4: 28 | AL4: 42 | AM4: 44 | AN4: 52 | AO4: 55 | AP4: 57 | AQ4: 59 | AR4: 60 | AS4: 61 | AT4: 66 | AU4: 67 | AV4: 69 | AW4: 70 | AX4: 71 | AY4: 72 | AZ4: 74 | BA4: 75 | BB4: 7 | BC4: 8 | BD4: 9 | BE4: 10 | BF4: 11 | BG4: 19 | BH4: 24 | BI4: 26 | BJ4: 36 | BK4: 47 | BL4: 49 | BM4: 51 | BN4: 53 | BO4: 54 | BP4: 56 | BQ4: 57 | BR4: 59 | BS4: 62 | BT4: 63 | BU4: 65 | BV4: 66 | BW4: 69 | BX4: 72 | BY4: 73 | BZ4: 76 | CA4: 77 | CB4: 78 | CC4: 81 | CD4: 82 | CE4: 86 | CF4: 7 | CG4: 8 | CH4: 9 | CI4: 10 | CJ4: 11 | CK4: 19 | CL4: 24 | CM4: 26 | CN4: 36 | CO4: 47 | CP4: 49 | CQ4: 51 | CR4: 53 | CS4: 54 | CT4: 56 | CU4: 57 | CV4: 59 | CW4: 62 | CX4: 63 | CY4: 65 | CZ4: 66 | DA4: 69 | DB4: 72 | DC4: 73 | DD4: 76 | DE4: 77 | DF4: 78 | DG4: 81 | DH4: 82 | DI4: 86 | DJ4: 1 | DK4: 5 | DL4: 8 | DM4: 9 | DN4: 11 | DO4: 12 | DP4: 14 | DQ4: 15 | DR4: 25 | DS4: 28 | DT4: 42 | DU4: 44 | DV4: 52 | DW4: 55 | DX4: 57 | DY4: 59 | DZ4: 60 | EA4: 61 | EB4: 66 | EC4: 67 | ED4: 69 | EE4: 70 | EF4: 71 | EG4: 72 | EH4: 74 | EI4: 75 | EJ4: 7 | EK4: 8 | EL4: 9 | EM4: 10 | EN4: 11 | EO4: 19 | EP4: 24 | EQ4: 26 | ER4: 36 | ES4: 47 | ET4: 49 | EU4: 51 | EV4: 53 | EW4: 54 | EX4: 56 | EY4: 57 | EZ4: 59 | FA4: 62 | FB4: 63 | FC4: 65 | FD4: 66 | FE4: 69 | FF4: 72 | FG4: 73 | FH4: 76 | FI4: 77 | FJ4: 78 | FK4: 81 | FL4: 82 | FM4: 86
A10: 1879 | B10: 56.2 | C10: 105.7 | D10: 70.1 | E10: 52.1 | F10: 65.3 | G10: 54.5 | H10: 115.2 | I10: 87.1 | J10: 64.6 | K10: 85.8 | L10: 81.2 | M10: 106.7 | N10: 60.1 | O10: #N/A | P10: 81.1 | Q10: 124.7 | R10: #N/A | S10: 127.4 | T10: 79.9 | U10: #N/A | V10: 169 | W10: 124.2 | X10: 116.2 | Y10: #N/A | Z10: #N/A | AA10: 98.2 | AB10: 305.2 | AC10: 155.1 | AD10: 613.6 | AE10: 167.2 | AF10: 48.8 | AG10: 1237.3 | AH10: 48.5 | AI10: 21 | AJ10: 41.6 | AK10: 17.5 | AL10: 39.9 | AM10: 20.3 | AN10: 19.3 | AO10: #N/A | AP10: 3.6 | AQ10: 19.6 | AR10: #N/A | AS10: 19.6 | AT10: 3 | AU10: #N/A | AV10: 0.2 | AW10: 3.5 | AX10: 4.1 | AY10: #N/A | AZ10: #N/A | BA10: 12.4 | BB10: 94 | BC10: 144.3 | BD10: 101.2 | BE10: 157.1 | BF10: #N/A | BG10: 184.9 | BH10: 87.8 | BI10: 95.6 | BJ10: 74.6 | BK10: #N/A | BL10: #N/A | BM10: 91.9 | BN10: 117.4 | BO10: 86 | BP10: 89.7 | BQ10: 144 | BR10: 108.3 | BS10: 121.8 | BT10: 51.5 | BU10: #N/A | BV10: #N/A | BW10: #N/A | BX10: #N/A | BY10: 63.6 | BZ10: 87.5 | CA10: 73.9 | CB10: 44.3 | CC10: 108.2 | CD10: 175 | CE10: 132.3 | CF10: 26.4 | CG10: 83.9 | CH10: 52.5 | CI10: 4.3 | CJ10: #N/A | CK10: 37.5 | CL10: 11.3 | CM10: 19.7 | CN10: 1.4 | CO10: #N/A | CP10: #N/A | CQ10: 18.5 | CR10: 31.8 | CS10: 43.6 | CT10: 167.8 | CU10: 8.6 | CV10: 76.5 | CW10: 19.7 | CX10: 40.6 | CY10: #N/A | CZ10: #N/A | DA10: #N/A | DB10: #N/A | DC10: 16.8 | DD10: 66.4 | DE10: 4.5 | DF10: 9.5 | DG10: 166.3 | DH10: 27.1 | DI10: 19.2 | DJ10: 10.1 | DK10: 217.5 | DL10: 16.6 | DM10: 53.8 | DN10: 25.6 | DO10: 17.8 | DP10: 37.7 | DQ10: 8.2 | DR10: 14.2 | DS10: 5.8 | DT10: 186.5 | DU10: 11 | DV10: 10.6 | DW10: 1.2 | DX10: 2 | DY10: 2.1 | DZ10: 0 | EA10: 35.2 | EB10: 3.7 | EC10: 0.7 | ED10: 0.1 | EE10: 5.9 | EF10: 10 | EG10: #N/A | EH10: 3.4 | EI10: 1.6 | EJ10: 11.7 | EK10: 19.9 | EL10: 55.6 | EM10: 1.3 | EN10: #N/A | EO10: 68.4 | EP10: 3.6 | EQ10: 20 | ER10: 8.2 | ES10: 22.9 | ET10: #N/A | EU10: 7.6 | EV10: 19.3 | EW10: 10.8 | EX10: 27.1 | EY10: 11.1 | EZ10: 27 | FA10: 6.2 | FB10: 4.6 | FC10: #N/A | FD10: 3.4 | FE10: #N/A | FF10: #N/A | FG10: 5 | FH10: 10.3 | FI10: 0.1 | FJ10: 5.2 | FK10: 26.2 | FL10: 6.4 | FM10: 24.8
A11: 1880 | B11: 53.8 | C11: 111.4 | D11: 69.1 | E11: 60.1 | F11: 77.8 | G11: 74.6 | H11: 122.3 | I11: 94.5 | J11: 69.1 | K11: 93.6 | L11: 91 | M11: 122.1 | N11: 65.7 | O11: #N/A | P11: 106.9 | Q11: 130.2 | R11: #N/A | S11: 143.5 | T11: 80.1 | U11: #N/A | V11: 232.5 | W11: 138.7 | X11: 123.4 | Y11: #N/A | Z11: #N/A | AA11: 105.1 | AB11: 579.2 | AC11: 160.3 | AD11: 696.2 | AE11: 182.3 | AF11: 59.3 | AG11: 1180.7 | AH11: 52.9 | AI11: 23.2 | AJ11: 49.5 | AK11: 19.7 | AL11: 45.7 | AM11: 18.3 | AN11: 19.9 | AO11: #N/A | AP11: 3.5 | AQ11: 24.3 | AR11: #N/A | AS11: 15.7 | AT11: 1.1 | AU11: #N/A | AV11: 0.2 | AW11: 3.8 | AX11: 4.1 | AY11: #N/A | AZ11: #N/A | BA11: 13 | BB11: 102.1 | BC11: 144.4 | BD11: 114.6 | BE11: 110.8 | BF11: #N/A | BG11: 226.6 | BH11: 93.3 | BI11: 107.5 | BJ11: 86 | BK11: #N/A | BL11: #N/A | BM11: 99 | BN11: 120.5 | BO11: 104.1 | BP11: 90.8 | BQ11: 137.4 | BR11: 105.9 | BS11: 141.3 | BT11: 58.9 | BU11: #N/A | BV11: #N/A | BW11: #N/A | BX11: #N/A | BY11: 67.7 | BZ11: 97.1 | CA11: 94.8 | CB11: 56.8 | CC11: 132.2 | CD11: 189.2 | CE11: 154.5 | CF11: 27.8 | CG11: 79.9 | CH11: 47.3 | CI11: 4.3 | CJ11: #N/A | CK11: 41.5 | CL11: 14.9 | CM11: 27.4 | CN11: 1.5 | CO11: #N/A | CP11: #N/A | CQ11: 21.5 | CR11: 40.6 | CS11: 70 | CT11: 220 | CU11: 9.3 | CV11: 103.9 | CW11: 30.1 | CX11: 57.1 | CY11: #N/A | CZ11: #N/A | DA11: #N/A | DB11: #N/A | DC11: 26.8 | DD11: 87.5 | DE11: 12.1 | DF11: 13.1 | DG11: 301.9 | DH11: 80.9 | DI11: 20.6 | DJ11: 18.3 | DK11: 236.8 | DL11: 18.6 | DM11: 67.7 | DN11: 37.1 | DO11: 23.2 | DP11: 43.7 | DQ11: 9.8 | DR11: 18.1 | DS11: 7.1 | DT11: 239.3 | DU11: 11.3 | DV11: 12 | DW11: 1.2 | DX11: 2.5 | DY11: 2.7 | DZ11: 0 | EA11: 31.8 | EB11: 1.4 | EC11: 0.8 | ED11: 0.2 | EE11: 7.2 | EF11: 10.7 | EG11: #N/A | EH11: 3.8 | EI11: 1.8 | EJ11: 13.4 | EK11: 18.9 | EL11: 56.8 | EM11: 0.9 | EN11: #N/A | EO11: 92.8 | EP11: 5 | EQ11: 31.2 | ER11: 10.2 | ES11: 32.7 | ET11: #N/A | EU11: 9.6 | EV11: 25.4 | EW11: 20.9 | EX11: 36 | EY11: 11.5 | EZ11: 35.9 | FA11: 10.9 | FB11: 7.4 | FC11: #N/A | FD11: 4.8 | FE11: #N/A | FF11: #N/A | FG11: 8.5 | FH11: 15 | FI11: 0.2 | FJ11: 9.1 | FK11: 58.1 | FL11: 20.7 | FM11: 31
A12: 1881 | B12: 68.9 | C12: 114.6 | D12: 76.4 | E12: 73.1 | F12: 100.9 | G12: 72.1 | H12: 124.4 | I12: 96.4 | J12: 72.8 | K12: 87.5 | L12: 87.9 | M12: 113 | N12: 70.1 | O12: #N/A | P12: 109.6 | Q12: 131.7 | R12: #N/A | S12: 136.5 | T12: 83.4 | U12: #N/A | V12: 194 | W12: 126.6 | X12: 112.1 | Y12: #N/A | Z12: #N/A | AA12: 104.3 | AB12: 297.7 | AC12: 122.2 | AD12: 592.1 | AE12: 141.7 | AF12: 45.6 | AG12: 1058.1 | AH12: 51.2 | AI12: 15.9 | AJ12: 47.8 | AK12: 20.3 | AL12: 43.9 | AM12: 23.8 | AN12: 22.2 | AO12: #N/A | AP12: 4.6 | AQ12: 27.7 | AR12: #N/A | AS12: 23.6 | AT12: 1.8 | AU12: #N/A | AV12: 0.4 | AW12: 5.1 | AX12: 5.7 | AY12: #N/A | AZ12: #N/A | BA12: 15 | BB12: 107.9 | BC12: 197.7 | BD12: 89 | BE12: 102.9 | BF12: #N/A | BG12: 224.7 | BH12: 94.3 | BI12: 104.9 | BJ12: 87.1 | BK12: #N/A | BL12: #N/A | BM12: 98.1 | BN12: 114.4 | BO12: 94.4 | BP12: 91.2 | BQ12: 133.3 | BR12: 108.8 | BS12: 126.6 | BT12: 63.3 | BU12: #N/A | BV12: #N/A | BW12: #N/A | BX12: #N/A | BY12: 81.3 | BZ12: 89.2 | CA12: 97.2 | CB12: 58.3 | CC12: 106.7 | CD12: 182.7 | CE12: 138.2 | CF12: 30 | CG12: 95.5 | CH12: 54.7 | CI12: 6.9 | CJ12: #N/A | CK12: 41.9 | CL12: 14.7 | CM12: 26.8 | CN12: 1.6 | CO12: #N/A | CP12: #N/A | CQ12: 25 | CR12: 38.1 | CS12: 35.7 | CT12: 192.4 | CU12: 9.4 | CV12: 95.2 | CW12: 28 | CX12: 59.6 | CY12: #N/A | CZ12: #N/A | DA12: #N/A | DB12: #N/A | DC12: 24.2 | DD12: 93.1 | DE12: 7.5 | DF12: 9.4 | DG12: 250.2 | DH12: 84.8 | DI12: 23.4 | DJ12: 12 | DK12: 185.7 | DL12: 17.5 | DM12: 64 | DN12: 37 | DO12: 20.1 | DP12: 43.1 | DQ12: 6.8 | DR12: 18.4 | DS12: 6.8 | DT12: 222.1 | DU12: 13.6 | DV12: 14.2 | DW12: 1.5 | DX12: 3.4 | DY12: 3.1 | DZ12: 0 | EA12: 45.5 | EB12: 2.3 | EC12: 1.1 | ED12: 0.3 | EE12: 8.7 | EF12: 13.4 | EG12: #N/A | EH12: 4.1 | EI12: 2 | EJ12: 15.3 | EK12: 21.6 | EL12: 50.9 | EM12: 1.4 | EN12: #N/A | EO12: 92.8 | EP12: 5 | EQ12: 29.8 | ER12: 10.9 | ES12: 31.6 | ET12: #N/A | EU12: 11 | EV12: 22.6 | EW12: 9.7 | EX12: 31.6 | EY12: 11.1 | EZ12: 33.8 | FA12: 9.1 | FB12: 8.4 | FC12: #N/A | FD12: 5.2 | FE12: #N/A | FF12: #N/A | FG12: 9.2 | FH12: 14.7 | FI12: 0.1 | FJ12: 6.7 | FK12: 38.9 | FL12: 21 | FM12: 31.6
A13: 1882 | B13: 79.4 | C13: 119.9 | D13: 83.4 | E13: 87.9 | F13: 110.2 | G13: 72.8 | H13: 129 | I13: 101 | J13: 72.1 | K13: 84.3 | L13: 87.7 | M13: 118.8 | N13: 71.8 | O13: #N/A | P13: 109.2 | Q13: 129.2 | R13: 186.7 | S13: 127 | T13: 83.1 | U13: #N/A | V13: 202.1 | W13: 125.4 | X13: 122.6 | Y13: #N/A | Z13: #N/A | AA13: 106.3 | AB13: 131.8 | AC13: 87 | AD13: 423.4 | AE13: 81.7 | AF13: 35.5 | AG13: 693.4 | AH13: 55.8 | AI13: 14.1 | AJ13: 49.4 | AK13: 22.4 | AL13: 44.5 | AM13: 22 | AN13: 28.1 | AO13: #N/A | AP13: 5.3 | AQ13: 30.8 | AR13: 4.9 | AS13: 23.1 | AT13: 1.3 | AU13: #N/A | AV13: 0.5 | AW13: 5.7 | AX13: 6.9 | AY13: #N/A | AZ13: #N/A | BA13: 16.9 | BB13: 114.9 | BC13: 131.2 | BD13: 73.8 | BE13: 104.8 | BF13: #N/A | BG13: 224.8 | BH13: 92.3 | BI13: 108.2 | BJ13: 109.2 | BK13: #N/A | BL13: #N/A | BM13: 105.9 | BN13: 116.1 | BO13: 91.3 | BP13: 91.6 | BQ13: 142.5 | BR13: 107.1 | BS13: 117.8 | BT13: 72.8 | BU13: #N/A | BV13: #N/A | BW13: #N/A | BX13: #N/A | BY13: 69.7 | BZ13: 92.5 | CA13: 106.9 | CB13: 64.1 | CC13: 107 | CD13: 175.3 | CE13: 136.3 | CF13: 35.1 | CG13: 80.2 | CH13: 59.4 | CI13: 6.4 | CJ13: #N/A | CK13: 49.2 | CL13: 17.4 | CM13: 23.8 | CN13: 2.1 | CO13: #N/A | CP13: #N/A | CQ13: 25.8 | CR13: 40.7 | CS13: 43.8 | CT13: 254.2 | CU13: 11.5 | CV13: 119.6 | CW13: 35.9 | CX13: 62 | CY13: #N/A | CZ13: #N/A | DA13: #N/A | DB13: #N/A | DC13: 29.3 | DD13: 101.5 | DE13: 8.7 | DF13: 11.8 | DG13: 304 | DH13: 73.5 | DI13: 25.8 | DJ13: 6.1 | DK13: 138.4 | DL13: 13.7 | DM13: 44.9 | DN13: 31.5 | DO13: 13.3 | DP13: 48.6 | DQ13: 6.4 | DR13: 18.9 | DS13: 7.2 | DT13: 224.6 | DU13: 13.2 | DV13: 18.4 | DW13: 1.7 | DX13: 3.9 | DY13: 3.4 | DZ13: 0.8 | EA13: 41.2 | EB13: 1.6 | EC13: 1.1 | ED13: 0.3 | EE13: 9.7 | EF13: 17.6 | EG13: #N/A | EH13: 4.7 | EI13: 2.3 | EJ13: 20 | EK13: 17.3 | EL13: 45.9 | EM13: 1.3 | EN13: #N/A | EO13: 109.1 | EP13: 5.8 | EQ13: 27.2 | ER13: 17.6 | ES13: 37.2 | ET13: #N/A | EU13: 12.3 | EV13: 24.6 | EW13: 11.5 | EX13: 41.9 | EY13: 14.6 | EZ13: 41.8 | FA13: 10.9 | FB13: 10 | FC13: #N/A | FD13: 6 | FE13: #N/A | FF13: #N/A | FG13: 9.7 | FH13: 16.6 | FI13: 0.2 | FJ13: 9.8 | FK13: 47.4 | FL13: 17.4 | FM13: 34.4
A14: 1883 | B14: 74 | C14: 114 | D14: 80.2 | E14: 83.1 | F14: 94.8 | G14: 69 | H14: 122 | I14: 89.8 | J14: 71.8 | K14: 86.8 | L14: 81.6 | M14: 112.5 | N14: 72.5 | O14: #N/A | P14: 108.2 | Q14: 129.7 | R14: 195.8 | S14: 128.4 | T14: 86.1 | U14: #N/A | V14: 176 | W14: 116.9 | X14: 124.3 | Y14: #N/A | Z14: #N/A | AA14: 103 | AB14: 419.4 | AC14: 80.9 | AD14: 622.1 | AE14: 98.5 | AF14: 44.1 | AG14: 881.4 | AH14: 68.6 | AI14: 19.7 | AJ14: 52.5 | AK14: 20.7 | AL14: 47.9 | AM14: 21.6 | AN14: 26.8 | AO14: #N/A | AP14: 7 | AQ14: 40.4 | AR14: 7 | AS14: 23.9 | AT14: 2.8 | AU14: #N/A | AV14: 0.4 | AW14: 5.4 | AX14: 7.8 | AY14: #N/A | AZ14: #N/A | BA14: 18 | BB14: 109.1 | BC14: 111.3 | BD14: 67.2 | BE14: 100.4 | BF14: #N/A | BG14: 203.7 | BH14: 88.5 | BI14: 104.7 | BJ14: 99.3 | BK14: #N/A | BL14: #N/A | BM14: 101.8 | BN14: 117.1 | BO14: 85.7 | BP14: 86.9 | BQ14: 122.8 | BR14: 108.3 | BS14: 115.8 | BT14: 72 | BU14: #N/A | BV14: #N/A | BW14: #N/A | BX14: #N/A | BY14: 53.3 | BZ14: 90.4 | CA14: 98.1 | CB14: 58.9 | CC14: 106.8 | CD14: 161.4 | CE14: 131.6 | CF14: 35 | CG14: 84 | CH14: 61.7 | CI14: 7.3 | CJ14: #N/A | CK14: 50.7 | CL14: 25.9 | CM14: 20.9 | CN14: 1.9 | CO14: #N/A | CP14: #N/A | CQ14: 25.8 | CR14: 39.9 | CS14: 47.9 | CT14: 273.5 | CU14: 12.3 | CV14: 100.5 | CW14: 31.2 | CX14: 57 | CY14: #N/A | CZ14: #N/A | DA14: #N/A | DB14: #N/A | DC14: 38.9 | DD14: 100.5 | DE14: 7.3 | DF14: 11.9 | DG14: 231.9 | DH14: 44.9 | DI14: 26.8 | DJ14: 18.2 | DK14: 122.3 | DL14: 19.3 | DM14: 51.1 | DN14: 33.6 | DO14: 16.1 | DP14: 56.5 | DQ14: 7.9 | DR14: 20 | DS14: 6.9 | DT14: 224.7 | DU14: 12.3 | DV14: 17.7 | DW14: 1.4 | DX14: 5.1 | DY14: 4.4 | DZ14: 1.1 | EA14: 43.3 | EB14: 3.7 | EC14: 1.1 | ED14: 0.3 | EE14: 8.4 | EF14: 20.2 | EG14: #N/A | EH14: 4.1 | EI14: 2.4 | EJ14: 19 | EK14: 15.3 | EL14: 43.4 | EM14: 1.4 | EN14: #N/A | EO14: 101.8 | EP14: 8.3 | EQ14: 23.1 | ER14: 14.8 | ES14: 34.3 | ET14: #N/A | EU14: 11.8 | EV14: 24.3 | EW14: 11.8 | EX14: 42.8 | EY14: 13.5 | EZ14: 35.5 | FA14: 9.3 | FB14: 9.1 | FC14: #N/A | FD14: 5.1 | FE14: #N/A | FF14: #N/A | FG14: 9.8 | FH14: 16 | FI14: 0.1 | FJ14: 9.1 | FK14: 36.1 | FL14: 9.8 | FM14: 34.4
A15: 1884 | B15: 75.2 | C15: 97.7 | D15: 79 | E15: 79.9 | F15: 82.8 | G15: 65.6 | H15: 110.8 | I15: 92.7 | J15: 83.9 | K15: 90.9 | L15: 82.8 | M15: 105 | N15: 67.8 | O15: #N/A | P15: 100.9 | Q15: 132 | R15: 206.3 | S15: 130.1 | T15: 79.5 | U15: #N/A | V15: 146.1 | W15: 119.2 | X15: 128.5 | Y15: #N/A | Z15: #N/A | AA15: 100.5 | AB15: 332.5 | AC15: 77.2 | AD15: 587.7 | AE15: 81.7 | AF15: 36.4 | AG15: 876.2 | AH15: 71.1 | AI15: 21 | AJ15: 44.9 | AK15: 22.8 | AL15: 46.5 | AM15: 20.3 | AN15: 26.3 | AO15: #N/A | AP15: 7.3 | AQ15: 54.6 | AR15: 8.4 | AS15: 23.6 | AT15: 3.4 | AU15: #N/A | AV15: 0.4 | AW15: 4.7 | AX15: 6.2 | AY15: #N/A | AZ15: #N/A | BA15: 15.7 | BB15: 108.4 | BC15: 106.1 | BD15: 73.3 | BE15: 103.8 | BF15: #N/A | BG15: 153.7 | BH15: 90.8 | BI15: 106 | BJ15: 66.1 | BK15: #N/A | BL15: #N/A | BM15: 91.1 | BN15: 104.4 | BO15: 82.8 | BP15: 86.6 | BQ15: 118.4 | BR15: 100.3 | BS15: 109 | BT15: 68.6 | BU15: #N/A | BV15: #N/A | BW15: #N/A | BX15: #N/A | BY15: 56.6 | BZ15: 92.3 | CA15: 84.9 | CB15: 50.9 | CC15: 101.6 | CD15: 159 | CE15: 134.7 | CF15: 34.1 | CG15: 84.9 | CH15: 61.1 | CI15: 7.3 | CJ15: #N/A | CK15: 58.6 | CL15: 19.4 | CM15: 20 | CN15: 1.9 | CO15: #N/A | CP15: #N/A | CQ15: 27.9 | CR15: 44 | CS15: 44.1 | CT15: 252.3 | CU15: 12.3 | CV15: 101.8 | CW15: 37.1 | CX15: 60.5 | CY15: #N/A | CZ15: #N/A | DA15: #N/A | DB15: #N/A | DC15: 29.1 | DD15: 85.7 | DE15: 20 | DF15: 11.7 | DG15: 193.5 | DH15: 33.8 | DI15: 23.5 | DJ15: 14.7 | DK15: 100 | DL15: 18 | DM15: 40.8 | DN15: 24.3 | DO15: 15.2 | DP15: 53.2 | DQ15: 8.7 | DR15: 20 | DS15: 8 | DT15: 221.6 | DU15: 10.8 | DV15: 16.2 | DW15: 1.3 | DX15: 5 | DY15: 6.1 | DZ15: 1.4 | EA15: 43.4 | EB15: 4.1 | EC15: 1.3 | ED15: 0.2 | EE15: 7.5 | EF15: 16.5 | EG15: #N/A | EH15: 4.1 | EI15: 2 | EJ15: 18.5 | EK15: 14.8 | EL15: 46.9 | EM15: 1.5 | EN15: #N/A | EO15: 88.8 | EP15: 6.4 | EQ15: 22.5 | ER15: 10.2 | ES15: 30.2 | ET15: #N/A | EU15: 11.4 | EV15: 26.6 | EW15: 10.5 | EX15: 39.3 | EY15: 13.1 | EZ15: 33.3 | FA15: 10.4 | FB15: 9.2 | FC15: #N/A | FD15: 5 | FE15: #N/A | FF15: #N/A | FG15: 7.8 | FH15: 14 | FI15: 0.3 | FJ15: 7.7 | FK15: 28.6 | FL15: 7.3 | FM15: 30.9
A16: 1885 | B16: 65.1 | C16: 92.4 | D16: 72.8 | E16: 64.5 | F16: 71.4 | G16: 55.9 | H16: 101.2 | I16: 85.1 | J16: 79.1 | K16: 90.3 | L16: 80.8 | M16: 94.7 | N16: 65 | O16: #N/A | P16: 93 | Q16: 127.9 | R16: 212.6 | S16: 126.9 | T16: 68.2 | U16: #N/A | V16: 125.8 | W16: 113 | X16: 116.9 | Y16: #N/A | Z16: #N/A | AA16: 89.4 | AB16: 375.6 | AC16: 67.7 | AD16: 668.3 | AE16: 99.9 | AF16: 45.8 | AG16: 762.8 | AH16: 72.6 | AI16: 24.1 | AJ16: 63.5 | AK16: 22.9 | AL16: 39.7 | AM16: 26.6 | AN16: 25.6 | AO16: #N/A | AP16: 6.6 | AQ16: 55.8 | AR16: 10.7 | AS16: 24.4 | AT16: 4 | AU16: #N/A | AV16: 0.5 | AW16: 4.3 | AX16: 5.1 | AY16: #N/A | AZ16: #N/A | BA16: 15.4 | BB16: 109.9 | BC16: 106.9 | BD16: 63.9 | BE16: 108.1 | BF16: #N/A | BG16: 135.5 | BH16: 90.5 | BI16: 102.2 | BJ16: 58.6 | BK16: #N/A | BL16: #N/A | BM16: 81.5 | BN16: 97.1 | BO16: 75.4 | BP16: 83.3 | BQ16: 111.1 | BR16: 94.7 | BS16: 103 | BT16: 64.5 | BU16: #N/A | BV16: #N/A | BW16: #N/A | BX16: #N/A | BY16: 46.5 | BZ16: 84.7 | CA16: 86.8 | CB16: 52.1 | CC16: 92.7 | CD16: 153.5 | CE16: 119.5 | CF16: 32.2 | CG16: 83.3 | CH16: 66.4 | CI16: 6.8 | CJ16: #N/A | CK16: 61.1 | CL16: 25.9 | CM16: 20.8 | CN16: 2.1 | CO16: #N/A | CP16: #N/A | CQ16: 31 | CR16: 44 | CS16: 59.6 | CT16: 237.1 | CU16: 14.2 | CV16: 82.4 | CW16: 32.4 | CX16: 54.8 | CY16: #N/A | CZ16: #N/A | DA16: #N/A | DB16: #N/A | DC16: 36 | DD16: 82.3 | DE16: 22.2 | DF16: 11.4 | DG16: 184.8 | DH16: 25.2 | DI16: 24.4 | DJ16: 14.3 | DK16: 83.1 | DL16: 18.8 | DM16: 40.3 | DN16: 26.3 | DO16: 11.3 | DP16: 49.6 | DQ16: 9.1 | DR16: 26.6 | DS16: 8 | DT16: 184.4 | DU16: 12.7 | DV16: 15.1 | DW16: 1.5 | DX16: 4.1 | DY16: 6 | DZ16: 1.9 | EA16: 43.6 | EB16: 4.1 | EC16: 1.2 | ED16: 0.2 | EE16: 6.6 | EF16: 12.5 | EG16: #N/A | EH16: 4 | EI16: 1.8 | EJ16: 17.7 | EK16: 14.6 | EL16: 44.4 | EM16: 1.4 | EN16: #N/A | EO16: 81.7 | EP16: 8.5 | EQ16: 22.6 | ER16: 9.7 | ES16: 27.9 | ET16: #N/A | EU16: 11.4 | EV16: 24.7 | EW16: 12.9 | EX16: 35.6 | EY16: 14.1 | EZ16: 25.5 | FA16: 8.6 | FB16: 7.8 | FC16: #N/A | FD16: 4.8 | FE16: #N/A | FF16: #N/A | FG16: 7.9 | FH16: 12.3 | FI16: 0.4 | FJ16: 7.7 | FK16: 24.9 | FL16: 5.2 | FM16: 28.5
A17: 1886 | B17: 64.5 | C17: 86.4 | D17: 68.4 | E17: 59.5 | F17: 64.4 | G17: 57.4 | H17: 95.9 | I17: 77.7 | J17: 77.2 | K17: 83.3 | L17: 74.7 | M17: 92.4 | N17: 64 | O17: #N/A | P17: 90.9 | Q17: 114.4 | R17: 193.9 | S17: 116.2 | T17: 64.6 | U17: #N/A | V17: 117.8 | W17: 103.1 | X17: 113.3 | Y17: #N/A | Z17: #N/A | AA17: 87.4 | AB17: 303.2 | AC17: 91.1 | AD17: 529.4 | AE17: 103.5 | AF17: 50.6 | AG17: 660.7 | AH17: 73 | AI17: 27.8 | AJ17: 69.4 | AK17: 24.5 | AL17: 50.1 | AM17: 31.9 | AN17: 23 | AO17: #N/A | AP17: 6.8 | AQ17: 52.3 | AR17: 11.6 | AS17: 26.3 | AT17: 2.3 | AU17: #N/A | AV17: 0.7 | AW17: 4.8 | AX17: 5 | AY17: #N/A | AZ17: #N/A | BA17: 17.6 | BB17: 99.7 | BC17: 101.7 | BD17: 65.2 | BE17: 106.9 | BF17: #N/A | BG17: 139.5 | BH17: 89.4 | BI17: 94.9 | BJ17: 69.9 | BK17: #N/A | BL17: #N/A | BM17: 78.4 | BN17: 91.9 | BO17: 72.4 | BP17: 81 | BQ17: 120.6 | BR17: 94.8 | BS17: 90.5 | BT17: 66.7 | BU17: #N/A | BV17: #N/A | BW17: #N/A | BX17: #N/A | BY17: 50.8 | BZ17: 79.7 | CA17: 101.1 | CB17: 60.6 | CC17: 87.1 | CD17: 143.6 | CE17: 119.2 | CF17: 34.9 | CG17: 95.1 | CH17: 64.6 | CI17: 8.9 | CJ17: #N/A | CK17: 64.7 | CL17: 23.8 | CM17: 26.6 | CN17: 2.6 | CO17: #N/A | CP17: #N/A | CQ17: 30.5 | CR17: 51.2 | CS17: 83.5 | CT17: 290.8 | CU17: 17.4 | CV17: 96.4 | CW17: 34.9 | CX17: 57 | CY17: #N/A | CZ17: #N/A | DA17: #N/A | DB17: #N/A | DC17: 43.6 | DD17: 96.7 | DE17: 18.6 | DF17: 14.5 | DG17: 262.1 | DH17: 34.4 | DI17: 26.3 | DJ17: 11.5 | DK17: 104.4 | DL17: 14 | DM17: 38.5 | DN17: 26.2 | DO17: 10 | DP17: 47.3 | DQ17: 9.6 | DR17: 28.3 | DS17: 7.8 | DT17: 215.4 | DU17: 14.9 | DV17: 13.4 | DW17: 1.5 | DX17: 4.2 | DY17: 5.1 | DZ17: 1.8 | EA17: 43.1 | EB17: 2.3 | EC17: 1 | ED17: 0.3 | EE17: 6.6 | EF17: 11.8 | EG17: #N/A | EH17: 4.6 | EI17: 2 | EJ17: 17.4 | EK17: 15.9 | EL17: 44.1 | EM17: 1.9 | EN17: #N/A | EO17: 89 | EP17: 7.7 | EQ17: 26.7 | ER17: 14.2 | ES17: 30.7 | ET17: #N/A | EU17: 10.8 | EV17: 27.3 | EW17: 17.4 | EX17: 42.4 | EY17: 18.9 | EZ17: 29.8 | FA17: 8.1 | FB17: 8.4 | FC17: #N/A | FD17: 5.5 | FE17: #N/A | FF17: #N/A | FG17: 10.5 | FH17: 13.6 | FI17: 0.3 | FJ17: 11.3 | FK17: 33.2 | FL17: 6.7 | FM17: 30.6
A18: 1887 | B18: 57.9 | C18: 89.8 | D18: 62.3 | E18: 66.1 | F18: 68.7 | G18: 66.6 | H18: 96.7 | I18: 80.6 | J18: 69.2 | K18: 83.5 | L18: 75.1 | M18: 94.1 | N18: 69.1 | O18: #N/A | P18: 95.1 | Q18: 109.9 | R18: 178.4 | S18: 109.8 | T18: 65 | U18: #N/A | V18: 125.1 | W18: 102 | X18: 111.5 | Y18: #N/A | Z18: #N/A | AA18: 87.5 | AB18: 277.9 | AC18: 86.7 | AD18: 522.7 | AE18: 95.8 | AF18: 47.7 | AG18: 636.1 | AH18: 88.6 | AI18: 23 | AJ18: 57.2 | AK18: 28.6 | AL18: 50 | AM18: 28.7 | AN18: 23.3 | AO18: #N/A | AP18: 8.5 | AQ18: 55.3 | AR18: 14 | AS18: 27 | AT18: 1.7 | AU18: #N/A | AV18: 0.5 | AW18: 5.3 | AX18: 5.7 | AY18: #N/A | AZ18: #N/A | BA18: 18.9 | BB18: 108.4 | BC18: 94.3 | BD18: 113.9 | BE18: 109 | BF18: #N/A | BG18: 123.4 | BH18: 93.6 | BI18: 84.9 | BJ18: 71.1 | BK18: #N/A | BL18: #N/A | BM18: 93.6 | BN18: 93.8 | BO18: 85.5 | BP18: 83.4 | BQ18: 122.7 | BR18: 93.6 | BS18: 83.7 | BT18: 67.2 | BU18: #N/A | BV18: #N/A | BW18: #N/A | BX18: #N/A | BY18: 53.8 | BZ18: 76.4 | CA18: 103.8 | CB18: 62.3 | CC18: 85.3 | CD18: 133 | CE18: 115.6 | CF18: 39.5 | CG18: 94.6 | CH18: 51.9 | CI18: 8.4 | CJ18: #N/A | CK18: 62.5 | CL18: 31.8 | CM18: 26.4 | CN18: 2.6 | CO18: #N/A | CP18: #N/A | CQ18: 32.8 | CR18: 51.6 | CS18: 63.6 | CT18: 288 | CU18: 17.5 | CV18: 108.1 | CW18: 42.5 | CX18: 63.6 | CY18: #N/A | CZ18: #N/A | DA18: #N/A | DB18: #N/A | DC18: 46.9 | DD18: 111.9 | DE18: 10.4 | DF18: 14.3 | DG18: 355.9 | DH18: 56.8 | DI18: 28 | DJ18: 9.4 | DK18: 103.4 | DL18: 12.6 | DM18: 39.5 | DN18: 26.4 | DO18: 11.2 | DP18: 57.9 | DQ18: 8.3 | DR18: 20.9 | DS18: 9.2 | DT18: 216 | DU18: 13.7 | DV18: 14.7 | DW18: 1.5 | DX18: 5.5 | DY18: 5.1 | DZ18: 2 | EA18: 41.8 | EB18: 1.7 | EC18: 1.3 | ED18: 0.2 | EE18: 7.3 | EF18: 13.2 | EG18: #N/A | EH18: 5 | EI18: 2.1 | EJ18: 21.4 | EK18: 14.6 | EL18: 61.9 | EM18: 1.8 | EN18: #N/A | EO18: 76 | EP18: 10.8 | EQ18: 23.7 | ER18: 14.4 | ES18: 30.2 | ET18: #N/A | EU18: 13.8 | EV18: 28.1 | EW18: 15.6 | EX18: 43.2 | EY18: 19.3 | EZ18: 33 | FA18: 9.2 | FB18: 9.5 | FC18: #N/A | FD18: 6.3 | FE18: #N/A | FF18: #N/A | FG18: 12 | FH18: 15.1 | FI18: 0.2 | FJ18: 11.5 | FK18: 44.2 | FL18: 10.2 | FM18: 31.6
A19: 1888 | B19: 64.2 | C19: 93.7 | D19: 65.6 | E19: 71.4 | F19: 80.3 | G19: 61.5 | H19: 99.6 | I19: 81.6 | J19: 74.8 | K19: 74.3 | L19: 77.7 | M19: 101.3 | N19: 71.6 | O19: #N/A | P19: 100 | Q19: 121.3 | R19: 174.8 | S19: 116.6 | T19: 96.8 | U19: #N/A | V19: 121.7 | W19: 97.5 | X19: 116.7 | Y19: #N/A | Z19: #N/A | AA19: 87.3 | AB19: 359.7 | AC19: 51.5 | AD19: 640.4 | AE19: 79.6 | AF19: 40.3 | AG19: 576.3 | AH19: 78.3 | AI19: 22.4 | AJ19: 47.2 | AK19: 29.8 | AL19: 50.4 | AM19: 20.8 | AN19: 26.1 | AO19: #N/A | AP19: 10.2 | AQ19: 53.2 | AR19: 14.7 | AS19: 26 | AT19: 3.6 | AU19: #N/A | AV19: 1.2 | AW19: 6.5 | AX19: 6.6 | AY19: #N/A | AZ19: #N/A | BA19: 19.3 | BB19: 96.2 | BC19: 84.8 | BD19: 100.3 | BE19: 106.3 | BF19: #N/A | BG19: 142.1 | BH19: 94.3 | BI19: 75.4 | BJ19: 63.4 | BK19: #N/A | BL19: #N/A | BM19: 99.9 | BN19: 89.6 | BO19: 78.6 | BP19: 79.9 | BQ19: 109.6 | BR19: 92.6 | BS19: 88.3 | BT19: 66.3 | BU19: #N/A | BV19: #N/A | BW19: #N/A | BX19: #N/A | BY19: 47.1 | BZ19: 74.9 | CA19: 112.5 | CB19: 67.5 | CC19: 85.8 | CD19: 135.3 | CE19: 106.8 | CF19: 42.8 | CG19: 98.7 | CH19: 61.4 | CI19: 11.2 | CJ19: #N/A | CK19: 62.8 | CL19: 26.7 | CM19: 31.5 | CN19: 2.8 | CO19: #N/A | CP19: #N/A | CQ19: 39.1 | CR19: 58.9 | CS19: 64.3 | CT19: 332.2 | CU19: 19.8 | CV19: 110 | CW19: 42.9 | CX19: 64.6 | CY19: #N/A | CZ19: #N/A | DA19: #N/A | DB19: #N/A | DC19: 52.9 | DD19: 117.5 | DE19: 19.9 | DF19: 15.2 | DG19: 253.5 | DH19: 47.4 | DI19: 29 | DJ19: 13.5 | DK19: 64 | DL19: 16.2 | DM19: 35.5 | DN19: 26 | DO19: 9.4 | DP19: 52.7 | DQ19: 8.2 | DR19: 18.7 | DS19: 8.5 | DT19: 225.1 | DU19: 10.7 | DV19: 17.1 | DW19: 1.6 | DX19: 6.9 | DY19: 5.5 | DZ19: 2.1 | EA19: 42.6 | EB19: 5.3 | EC19: 1.5 | ED19: 0.5 | EE19: 8.5 | EF19: 16.2 | EG19: #N/A | EH19: 4.8 | EI19: 2.2 | EJ19: 20.6 | EK19: 13.7 | EL19: 64.4 | EM19: 2.4 | EN19: #N/A | EO19: 88 | EP19: 9.1 | EQ19: 25.1 | ER19: 14.2 | ES19: 28.6 | ET19: #N/A | EU19: 18 | EV19: 30.6 | EW19: 14.5 | EX19: 47.8 | EY19: 19.5 | EZ19: 33.3 | FA19: 9.7 | FB19: 9.5 | FC19: #N/A | FD19: 6.5 | FE19: #N/A | FF19: #N/A | FG19: 11.8 | FH19: 15.5 | FI19: 0.4 | FJ19: 13.3 | FK19: 31.7 | FL19: 8.7 | FM19: 30.2
A20: 1889 | B20: 52.2 | C20: 83.2 | D20: 58.9 | E20: 63.9 | F20: 70.7 | G20: 58.6 | H20: 102 | I20: 81 | J20: 71.3 | K20: 71 | L20: 78 | M20: 103.8 | N20: 70.7 | O20: #N/A | P20: 97.5 | Q20: 124.1 | R20: 161.2 | S20: 107.5 | T20: 73.2 | U20: #N/A | V20: 114.6 | W20: 96.1 | X20: 115.8 | Y20: #N/A | Z20: #N/A | AA20: 85.9 | AB20: 881.7 | AC20: 69.2 | AD20: 1007.2 | AE20: 119.8 | AF20: 60.9 | AG20: 821.5 | AH20: 77.4 | AI20: 28.9 | AJ20: 58.2 | AK20: 40.2 | AL20: 59.4 | AM20: 19.3 | AN20: 31.7 | AO20: #N/A | AP20: 9.8 | AQ20: 58.4 | AR20: 17.4 | AS20: 31.1 | AT20: 2 | AU20: #N/A | AV20: 0.8 | AW20: 7.1 | AX20: 9.5 | AY20: #N/A | AZ20: #N/A | BA20: 22.6 | BB20: 86.6 | BC20: 81.3 | BD20: 115.8 | BE20: 94.9 | BF20: 155.8 | BG20: 176.9 | BH20: 94.3 | BI20: 71 | BJ20: 59.7 | BK20: #N/A | BL20: 63.9 | BM20: 112.2 | BN20: 93.8 | BO20: 81.4 | BP20: 78.6 | BQ20: 114.1 | BR20: 97 | BS20: 93.6 | BT20: 66.8 | BU20: 149.5 | BV20: #N/A | BW20: #N/A | BX20: #N/A | BY20: 66 | BZ20: 79.1 | CA20: 90.3 | CB20: 54.2 | CC20: 88.6 | CD20: 142.5 | CE20: 103.8 | CF20: 39.1 | CG20: 89.6 | CH20: 64.3 | CI20: 10.2 | CJ20: 15.8 | CK20: 58.5 | CL20: 40.2 | CM20: 29.8 | CN20: 2.6 | CO20: #N/A | CP20: 23.4 | CQ20: 46.8 | CR20: 55.5 | CS20: 79.8 | CT20: 358.1 | CU20: 21 | CV20: 115.7 | CW20: 41.1 | CX20: 69.8 | CY20: 7.3 | CZ20: #N/A | DA20: #N/A | DB20: #N/A | DC20: 43.3 | DD20: 106.4 | DE20: 23.4 | DF20: 17 | DG20: 246.2 | DH20: 38.6 | DI20: 31.4 | DJ20: 27 | DK20: 76.4 | DL20: 22.9 | DM20: 47.9 | DN20: 34.6 | DO20: 12.7 | DP20: 53.3 | DQ20: 10.4 | DR20: 22 | DS20: 11 | DT20: 266.6 | DU20: 10.4 | DV20: 20.5 | DW20: 1.2 | DX20: 6.4 | DY20: 6.1 | DZ20: 2.3 | EA20: 47.2 | EB20: 2.2 | EC20: 1.4 | ED20: 0.3 | EE20: 9.2 | EF20: 22.9 | EG20: #N/A | EH20: 3.3 | EI20: 4.2 | EJ20: 11 | EK20: 12 | EL20: 77.9 | EM20: 1.9 | EN20: 3.8 | EO20: 102.1 | EP20: 13.8 | EQ20: 22.4 | ER20: 12.5 | ES20: 27.8 | ET20: 6.2 | EU20: 20.8 | EV20: 22.1 | EW20: 18.7 | EX20: 48.3 | EY20: 21.5 | EZ20: 36.6 | FA20: 9.9 | FB20: 10.3 | FC20: 1.7 | FD20: 6.6 | FE20: #N/A | FF20: #N/A | FG20: 13.6 | FH20: 14.9 | FI20: 0.9 | FJ20: 10.5 | FK20: 31.8 | FL20: 7.4 | FM20: 29.7
A21: 1890 | B21: 55.8 | C21: 83.5 | D21: 58.9 | E21: 59.9 | F21: 65.7 | G21: 55.3 | H21: 98.8 | I21: 77.8 | J21: 71.3 | K21: 70.6 | L21: 78.9 | M21: 100.3 | N21: 69.3 | O21: #N/A | P21: 100.8 | Q21: 116.7 | R21: 141.2 | S21: 103.1 | T21: 79.6 | U21: #N/A | V21: 115.1 | W21: 97.9 | X21: 112.9 | Y21: #N/A | Z21: #N/A | AA21: 89.4 | AB21: 1056.3 | AC21: 77.3 | AD21: 1254.3 | AE21: 138.5 | AF21: 84.8 | AG21: 797.4 | AH21: 84 | AI21: 37.9 | AJ21: 56 | AK21: 40.6 | AL21: 56 | AM21: 21.4 | AN21: 30.2 | AO21: #N/A | AP21: 10.7 | AQ21: 66.2 | AR21: 25.3 | AS21: 31.5 | AT21: 1.3 | AU21: #N/A | AV21: 1.1 | AW21: 8.5 | AX21: 10.4 | AY21: #N/A | AZ21: #N/A | BA21: 24.4 | BB21: 105.7 | BC21: 85.5 | BD21: 133.6 | BE21: 101.4 | BF21: 165 | BG21: 146 | BH21: 96.2 | BI21: 63.2 | BJ21: 74.2 | BK21: #N/A | BL21: 59.8 | BM21: 90.9 | BN21: 91.5 | BO21: 83.3 | BP21: 77.8 | BQ21: 126.3 | BR21: 95.8 | BS21: 91.4 | BT21: 63.5 | BU21: 165.6 | BV21: #N/A | BW21: #N/A | BX21: #N/A | BY21: 74.6 | BZ21: 85.3 | CA21: 92.5 | CB21: 57.2 | CC21: 102.5 | CD21: 137.2 | CE21: 106.7 | CF21: 46.9 | CG21: 100.8 | CH21: 57.6 | CI21: 13.2 | CJ21: 23 | CK21: 66 | CL21: 52.6 | CM21: 3.9 | CN21: 2.8 | CO21: #N/A | CP21: 24.5 | CQ21: 42.6 | CR21: 60.8 | CS21: 64.6 | CT21: 381.2 | CU21: 16.4 | CV21: 132.5 | CW21: 43.5 | CX21: 73.6 | CY21: 6.5 | CZ21: #N/A | DA21: #N/A | DB21: #N/A | DC21: 41.1 | DD21: 111.2 | DE21: 42.5 | DF21: 19.4 | DG21: 228.4 | DH21: 42.3 | DI21: 35.6 | DJ21: 34.6 | DK21: 85.6 | DL21: 28.6 | DM21: 51.9 | DN21: 44.9 | DO21: 11.6 | DP21: 56 | DQ21: 13.2 | DR21: 21.2 | DS21: 11 | DT21: 254.3 | DU21: 11.1 | DV21: 19.3 | DW21: 1.2 | DX21: 7.3 | DY21: 6.5 | DZ21: 2.9 | EA21: 45.7 | EB21: 1.6 | EC21: 1.4 | ED21: 0.4 | EE21: 11.2 | EF21: 24.6 | EG21: #N/A | EH21: 4.1 | EI21: 4.7 | EJ21: 16.1 | EK21: 14.1 | EL21: 80.6 | EM21: 2.6 | EN21: 5.8 | EO21: 95 | EP21: 18.4 | EQ21: 26.1 | ER21: 16.7 | ES21: 33 | ET21: 6.1 | EU21: 15.4 | EV21: 23.6 | EW21: 15.5 | EX21: 50.9 | EY21: 18.6 | EZ21: 41.4 | FA21: 10.2 | FB21: 10.3 | FC21: 1.7 | FD21: 7.1 | FE21: #N/A | FF21: #N/A | FG21: 14.5 | FH21: 16.7 | FI21: 1.7 | FJ21: 12.7 | FK21: 34.1 | FL21: 7.8 | FM21: 34.6
A22: 1891 | B22: 68 | C22: 108.4 | D22: 63.1 | E22: 61 | F22: 67.4 | G22: 60.8 | H22: 105.8 | I22: 78.6 | J22: 71.5 | K22: 71.5 | L22: 72.8 | M22: 94.1 | N22: 69.2 | O22: #N/A | P22: 102.5 | Q22: 95.6 | R22: 176.5 | S22: 95.1 | T22: 81.2 | U22: #N/A | V22: 117.8 | W22: 94.6 | X22: 111.8 | Y22: #N/A | Z22: #N/A | AA22: 89.3 | AB22: 740.4 | AC22: 114.4 | AD22: 1168 | AE22: 130.3 | AF22: 71.5 | AG22: 614 | AH22: 95.5 | AI22: 34.1 | AJ22: 53.8 | AK22: 43.8 | AL22: 66.1 | AM22: 28.5 | AN22: 26 | AO22: #N/A | AP22: 12.6 | AQ22: 66.3 | AR22: 27.6 | AS22: 30.5 | AT22: 7.6 | AU22: #N/A | AV22: 1 | AW22: 9.1 | AX22: 11.5 | AY22: #N/A | AZ22: #N/A | BA22: 23.4 | BB22: 113.1 | BC22: 87.6 | BD22: 124.2 | BE22: 116.7 | BF22: 165 | BG22: 147.9 | BH22: 76.4 | BI22: 59.5 | BJ22: 74.8 | BK22: 84.6 | BL22: 56.8 | BM22: 90.3 | BN22: 91.5 | BO22: 75.4 | BP22: 78.6 | BQ22: 103 | BR22: 91.4 | BS22: 84.8 | BT22: 59.9 | BU22: 166.3 | BV22: #N/A | BW22: #N/A | BX22: #N/A | BY22: 57.6 | BZ22: 88.9 | CA22: 123.2 | CB22: 54.5 | CC22: 107.8 | CD22: 122.3 | CE22: 113.3 | CF22: 37.6 | CG22: 98.8 | CH22: 68.2 | CI22: 12.8 | CJ22: 20.4 | CK22: 94.8 | CL22: 29.9 | CM22: 41.1 | CN22: 3.1 | CO22: 51.1 | CP22: 26.9 | CQ22: 50.3 | CR22: 48.7 | CS22: 86.6 | CT22: 246.4 | CU22: 25.3 | CV22: 112.2 | CW22: 47.3 | CX22: 78.7 | CY22: 7.3 | CZ22: #N/A | DA22: #N/A | DB22: #N/A | DC22: 50.3 | DD22: 113.5 | DE22: 27.3 | DF22: 25.2 | DG22: 210.9 | DH22: 34.4 | DI22: 33.1 | DJ22: 29.5 | DK22: 164.4 | DL22: 28.5 | DM22: 49.7 | DN22: 38.7 | DO22: 9.8 | DP22: 68.2 | DQ22: 11.9 | DR22: 20.4 | DS22: 12 | DT22: 277 | DU22: 13.9 | DV22: 16.4 | DW22: 1.3 | DX22: 8.7 | DY22: 5.4 | DZ22: 4 | EA22: 40.8 | EB22: 9.3 | EC22: 1.6 | ED22: 0.4 | EE22: 11.6 | EF22: 26.7 | EG22: #N/A | EH22: 3.8 | EI22: 4.5 | EJ22: 13.8 | EK22: 14.2 | EL22: 88.6 | EM22: 2.9 | EN22: 5.2 | EO22: 138.2 | EP22: 8.3 | EQ22: 25.9 | ER22: 18.5 | ES22: 25.8 | ET22: 6.4 | EU22: 18 | EV22: 21.6 | EW22: 18.8 | EX22: 33.2 | EY22: 23.4 | EZ22: 33.5 | FA22: 10.3 | FB22: 10.4 | FC22: 1.9 | FD22: 7.2 | FE22: #N/A | FF22: #N/A | FG22: 13.8 | FH22: 17.8 | FI22: 3.7 | FJ22: 15.7 | FK22: 33.1 | FL22: 5.7 | FM22: 34.1
A23: 1892 | B23: 60.2 | C23: 93.9 | D23: 63.1 | E23: 64.9 | F23: 71.9 | G23: 63.5 | H23: 100.7 | I23: 77.3 | J23: 73.3 | K23: 73.4 | L23: 65.6 | M23: 87.1 | N23: 65.5 | O23: #N/A | P23: 102.2 | Q23: 77.5 | R23: 171.8 | S23: 80.6 | T23: 74.1 | U23: #N/A | V23: 122.3 | W23: 89.1 | X23: 105.9 | Y23: #N/A | Z23: #N/A | AA23: 86.7 | AB23: 1024 | AC23: 130 | AD23: 1276.8 | AE23: 139.4 | AF23: 80.5 | AG23: 600.9 | AH23: 126.9 | AI23: 44.4 | AJ23: 56 | AK23: 35.2 | AL23: 57.5 | AM23: 28.3 | AN23: 31.4 | AO23: #N/A | AP23: 12.7 | AQ23: 71.5 | AR23: 29.6 | AS23: 33.5 | AT23: 3.8 | AU23: #N/A | AV23: 0.9 | AW23: 9.5 | AX23: 10.5 | AY23: #N/A | AZ23: #N/A | BA23: 24 | BB23: 114.1 | BC23: 85.2 | BD23: 113.7 | BE23: 114.3 | BF23: 137.5 | BG23: 143.9 | BH23: 83.2 | BI23: 56.3 | BJ23: 67.3 | BK23: 81.1 | BL23: 60.5 | BM23: 79.6 | BN23: 89.5 | BO23: 69.7 | BP23: 75.3 | BQ23: 112.3 | BR23: 96.2 | BS23: 84.6 | BT23: 62.9 | BU23: 171.3 | BV23: #N/A | BW23: #N/A | BX23: #N/A | BY23: 57.8 | BZ23: 80.5 | CA23: 121.7 | CB23: 55 | CC23: 90.8 | CD23: 124.1 | CE23: 114.2 | CF23: 39.1 | CG23: 102.9 | CH23: 72.4 | CI23: 15.8 | CJ23: 23.8 | CK23: 76.2 | CL23: 45.6 | CM23: 47.2 | CN23: 3.1 | CO23: 60.7 | CP23: 24.7 | CQ23: 51.3 | CR23: 56.3 | CS23: 105.6 | CT23: 284.5 | CU23: 27.9 | CV23: 107.7 | CW23: 55.8 | CX23: 78 | CY23: 8.1 | CZ23: #N/A | DA23: #N/A | DB23: #N/A | DC23: 54.5 | DD23: 128.5 | DE23: 37.6 | DF23: 25.3 | DG23: 185.6 | DH23: 37 | DI23: 35.2 | DJ23: 36.1 | DK23: 161.9 | DL23: 31.1 | DM23: 56.5 | DN23: 46.5 | DO23: 10.1 | DP23: 86.3 | DQ23: 15.3 | DR23: 21.7 | DS23: 9.9 | DT23: 217.1 | DU23: 12.7 | DV23: 18.7 | DW23: 1.5 | DX23: 8.7 | DY23: 4.7 | DZ23: 4.2 | EA23: 38 | EB23: 4.2 | EC23: 1.5 | ED23: 0.4 | EE23: 11.4 | EF23: 23.3 | EG23: #N/A | EH23: 4.2 | EI23: 4.5 | EJ23: 14.5 | EK23: 14.4 | EL23: 86.1 | EM23: 3.6 | EN23: 5 | EO23: 108.1 | EP23: 13.8 | EQ23: 28.1 | ER23: 16.7 | ES23: 29.4 | ET23: 6.2 | EU23: 16.2 | EV23: 24.4 | EW23: 21.2 | EX23: 36.7 | EY23: 28.1 | EZ23: 33.8 | FA23: 12.2 | FB23: 10.9 | FC23: 2.2 | FD23: 7.5 | FE23: #N/A | FF23: #N/A | FG23: 15 | FH23: 18.3 | FI23: 5.1 | FJ23: 15.9 | FK23: 24.6 | FL23: 6.2 | FM23: 36.6
A24: 1893 | B24: 64.7 | C24: 80.2 | D24: 67.6 | E24: 82.7 | F24: 90.9 | G24: 66.8 | H24: 92.9 | I24: 86.4 | J24: 74.5 | K24: 71.6 | L24: 64.7 | M24: 93.5 | N24: 65.8 | O24: #N/A | P24: 95.9 | Q24: 59.4 | R24: 132.6 | S24: 68.3 | T24: 66 | U24: #N/A | V24: 102.9 | W24: 87.5 | X24: 104.8 | Y24: #N/A | Z24: #N/A | AA24: 89.4 | AB24: 613.3 | AC24: 105.7 | AD24: 938 | AE24: 99.7 | AF24: 64.6 | AG24: 475.5 | AH24: 119.4 | AI24: 37.7 | AJ24: 60.4 | AK24: 44.1 | AL24: 54.8 | AM24: 26.9 | AN24: 29.3 | AO24: #N/A | AP24: 18.9 | AQ24: 78.9 | AR24: 42 | AS24: 39.4 | AT24: 15.3 | AU24: #N/A | AV24: 1.7 | AW24: 10.9 | AX24: 12 | AY24: #N/A | AZ24: #N/A | BA24: 23.3 | BB24: 101.2 | BC24: 86.3 | BD24: 132.3 | BE24: 129.2 | BF24: 146.7 | BG24: 159.8 | BH24: 89.6 | BI24: 53.5 | BJ24: 73.7 | BK24: 80.7 | BL24: 55.3 | BM24: 79.2 | BN24: 90.2 | BO24: 70.6 | BP24: 74.8 | BQ24: 117.6 | BR24: 101.9 | BS24: 86 | BT24: 62.4 | BU24: 177.7 | BV24: #N/A | BW24: #N/A | BX24: #N/A | BY24: 67.1 | BZ24: 74.2 | CA24: 103.2 | CB24: 55.1 | CC24: 88 | CD24: 121 | CE24: 112.6 | CF24: 42.2 | CG24: 92.6 | CH24: 63.7 | CI24: 13.6 | CJ24: 23.9 | CK24: 78.5 | CL24: 35.4 | CM24: 40.2 | CN24: 3.3 | CO24: 61.1 | CP24: 24.6 | CQ24: 54.6 | CR24: 52.2 | CS24: 68.7 | CT24: 230.7 | CU24: 16.2 | CV24: 105 | CW24: 52.9 | CX24: 74.4 | CY24: 9.1 | CZ24: #N/A | DA24: #N/A | DB24: #N/A | DC24: 36.3 | DD24: 123.4 | DE24: 62 | DF24: 23.4 | DG24: 170.8 | DH24: 31.7 | DI24: 33.9 | DJ24: 23.3 | DK24: 112.5 | DL24: 24.5 | DM24: 51.5 | DN24: 47.3 | DO24: 8.4 | DP24: 74.9 | DQ24: 14.5 | DR24: 23.8 | DS24: 12.1 | DT24: 204.1 | DU24: 13 | DV24: 17.6 | DW24: 1.7 | DX24: 12.3 | DY24: 4 | DZ24: 4.6 | EA24: 37.9 | EB24: 15.2 | EC24: 2.5 | ED24: 0.6 | EE24: 12.8 | EF24: 26.3 | EG24: #N/A | EH24: 4.4 | EI24: 4.5 | EJ24: 13.9 | EK24: 13.1 | EL24: 88.2 | EM24: 3.5 | EN24: 5.4 | EO24: 123.7 | EP24: 11.5 | EQ24: 22.8 | ER24: 19.2 | ES24: 29.5 | ET24: 5.7 | EU24: 17.1 | EV24: 22.8 | EW24: 14 | EX24: 29.6 | EY24: 17.1 | EZ24: 34.9 | FA24: 11.7 | FB24: 10.3 | FC24: 2.6 | FD24: 7.5 | FE24: #N/A | FF24: #N/A | FG24: 11.5 | FH24: 16.2 | FI24: 7.1 | FJ24: 14.8 | FK24: 21.9 | FL24: 5.2 | FM24: 34.8
A25: 1894 | B25: 59 | C25: 69.7 | D25: 64.7 | E25: 69.4 | F25: 75.1 | G25: 63.9 | H25: 78.6 | I25: 75.8 | J25: 71.9 | K25: 68.1 | L25: 50.8 | M25: 85.7 | N25: 65.3 | O25: #N/A | P25: 87 | Q25: 70 | R25: 111.3 | S25: 63.7 | T25: 60.2 | U25: #N/A | V25: 84.9 | W25: 79.7 | X25: 102.3 | Y25: #N/A | Z25: #N/A | AA25: 81.5 | AB25: 1178.3 | AC25: 68.4 | AD25: 1054.5 | AE25: 125 | AF25: 83.9 | AG25: 511.3 | AH25: 117.4 | AI25: 38.3 | AJ25: 67.7 | AK25: 50.1 | AL25: 68.6 | AM25: 32.7 | AN25: 32.7 | AO25: #N/A | AP25: 19.3 | AQ25: 78.7 | AR25: 36 | AS25: 40.8 | AT25: 17.6 | AU25: #N/A | AV25: 2.1 | AW25: 12.4 | AX25: 11.3 | AY25: #N/A | AZ25: #N/A | BA25: 26.9 | BB25: 78.3 | BC25: 74.1 | BD25: 125.9 | BE25: 94 | BF25: 165 | BG25: 128 | BH25: 93.7 | BI25: 55 | BJ25: 69.6 | BK25: 77.7 | BL25: 54.8 | BM25: 56.9 | BN25: 86.6 | BO25: 63.4 | BP25: 73.8 | BQ25: 88.5 | BR25: 91.2 | BS25: 90.9 | BT25: 66.2 | BU25: 161.1 | BV25: #N/A | BW25: #N/A | BX25: #N/A | BY25: 54.2 | BZ25: 64.5 | CA25: 81.7 | CB25: 42.8 | CC25: 84.3 | CD25: 112.1 | CE25: 98.4 | CF25: 44.7 | CG25: 114.7 | CH25: 71 | CI25: 13.3 | CJ25: 19.5 | CK25: 84.9 | CL25: 44.3 | CM25: 31.8 | CN25: 2.9 | CO25: 52.9 | CP25: 22.4 | CQ25: 41.5 | CR25: 49 | CS25: 72.7 | CT25: 130.6 | CU25: 28.1 | CV25: 88.1 | CW25: 41.5 | CX25: 50.5 | CY25: 4.3 | CZ25: #N/A | DA25: #N/A | DB25: #N/A | DC25: 31.2 | DD25: 116.2 | DE25: 50.5 | DF25: 20.5 | DG25: 128.7 | DH25: 28.1 | DI25: 34.3 | DJ25: 40.8 | DK25: 63.3 | DL25: 26.4 | DM25: 54.2 | DN25: 50.6 | DO25: 8.6 | DP25: 62.3 | DQ25: 13 | DR25: 25.8 | DS25: 13.1 | DT25: 200.4 | DU25: 14.5 | DV25: 19.4 | DW25: 2.1 | DX25: 11.3 | DY25: 4.7 | DZ25: 3.3 | EA25: 36.6 | EB25: 15.9 | EC25: 2.4 | ED25: 0.7 | EE25: 13.3 | EF25: 24 | EG25: #N/A | EH25: 5 | EI25: 4.7 | EJ25: 11.4 | EK25: 13.9 | EL25: 93.5 | EM25: 2.5 | EN25: 5 | EO25: 107.1 | EP25: 15.1 | EQ25: 18.5 | ER25: 16.2 | ES25: 24.5 | ET25: 5.1 | EU25: 9.4 | EV25: 20.5 | EW25: 13.3 | EX25: 16.5 | EY25: 22.3 | EZ25: 26.2 | FA25: 9.7 | FB25: 7.4 | FC25: 1.1 | FD25: 5.9 | FE25: #N/A | FF25: #N/A | FG25: 8 | FH25: 13.2 | FI25: 4.6 | FJ25: 10 | FK25: 15.8 | FL25: 3.8 | FM25: 30.7
A26: 1895 | B26: 64 | C26: 70.6 | D26: 67.3 | E26: 65.2 | F26: 66.2 | G26: 56.8 | H26: 74.4 | I26: 63.8 | J26: 71.5 | K26: 81.9 | L26: 53.3 | M26: 81.3 | N26: 60.4 | O26: #N/A | P26: 81.6 | Q26: 93.3 | R26: 113.8 | S26: 90.8 | T26: 65.4 | U26: #N/A | V26: 94.4 | W26: 81.1 | X26: 109.1 | Y26: #N/A | Z26: #N/A | AA26: 75.6 | AB26: 812 | AC26: 75.7 | AD26: 989.3 | AE26: 133.9 | AF26: 84.8 | AG26: 389.5 | AH26: 108.2 | AI26: 50.1 | AJ26: 65.3 | AK26: 51.6 | AL26: 62 | AM26: 33.3 | AN26: 36.1 | AO26: #N/A | AP26: 19.5 | AQ26: 79.6 | AR26: 48.4 | AS26: 39.7 | AT26: 13 | AU26: #N/A | AV26: 2.1 | AW26: 14.4 | AX26: 12.4 | AY26: #N/A | AZ26: #N/A | BA26: 34.3 | BB26: 79.6 | BC26: 73.8 | BD26: 122.4 | BE26: 84.5 | BF26: 137.5 | BG26: 94.7 | BH26: 86.1 | BI26: 60 | BJ26: 70.2 | BK26: 76.9 | BL26: 52.8 | BM26: 49.7 | BN26: 78.9 | BO26: 66.2 | BP26: 75.3 | BQ26: 97.3 | BR26: 93.5 | BS26: 85.8 | BT26: 60.4 | BU26: 108.6 | BV26: #N/A | BW26: #N/A | BX26: #N/A | BY26: 58.5 | BZ26: 68.6 | CA26: 72.7 | CB26: 39.8 | CC26: 80.8 | CD26: 116.6 | CE26: 91.9 | CF26: 45 | CG26: 110 | CH26: 75.3 | CI26: 19.2 | CJ26: 21.4 | CK26: 73.6 | CL26: 48.7 | CM26: 57.3 | CN26: 3.5 | CO26: 74.4 | CP26: 28.2 | CQ26: 53.1 | CR26: 67.7 | CS26: 177.3 | CT26: 431.5 | CU26: 32.7 | CV26: 104.4 | CW26: 49.2 | CX26: 70.6 | CY26: 5.9 | CZ26: #N/A | DA26: #N/A | DB26: #N/A | DC26: 28.1 | DD26: 155.3 | DE26: 32.2 | DF26: 30.4 | DG26: 145.4 | DH26: 47.8 | DI26: 40.2 | DJ26: 30.5 | DK26: 70.9 | DL26: 25.7 | DM26: 54.5 | DN26: 45.2 | DO26: 5.8 | DP26: 54.4 | DQ26: 14.3 | DR26: 24.7 | DS26: 16.2 | DT26: 189.9 | DU26: 14 | DV26: 19.9 | DW26: 2.4 | DX26: 10.8 | DY26: 6.3 | DZ26: 4.5 | EA26: 50.8 | EB26: 13.1 | EC26: 2.7 | ED26: 0.7 | EE26: 15.7 | EF26: 28.2 | EG26: #N/A | EH26: 5.7 | EI26: 5.6 | EJ26: 11.6 | EK26: 13.3 | EL26: 96.5 | EM26: 3.2 | EN26: 4.5 | EO26: 68.7 | EP26: 15.2 | EQ26: 36.4 | ER26: 19.3 | ES26: 34.2 | ET26: 6.2 | EU26: 10.5 | EV26: 25.8 | EW26: 33.8 | EX26: 55.7 | EY26: 28.6 | EZ26: 31.9 | FA26: 10.9 | FB26: 9.4 | FC26: 1 | FD26: 6.6 | FE26: #N/A | FF26: #N/A | FG26: 7.8 | FH26: 18.8 | FI26: 3.3 | FJ26: 13.4 | FK26: 17.1 | FL26: 6.4 | FM26: 33.6
A27: 1896 | B27: 56.4 | C27: 65.9 | D27: 61.2 | E27: 57.8 | F27: 52.2 | G27: 55.6 | H27: 76.5 | I27: 60.5 | J27: 68.8 | K27: 73.9 | L27: 59.8 | M27: 83.8 | N27: 62.7 | O27: #N/A | P27: 86.1 | Q27: 88 | R27: 117.1 | S27: 93.4 | T27: 69.5 | U27: #N/A | V27: 100.2 | W27: 81.7 | X27: 127.5 | Y27: #N/A | Z27: #N/A | AA27: 79.1 | AB27: 1180.1 | AC27: 137.2 | AD27: 1376.4 | AE27: 141.7 | AF27: 90.7 | AG27: 555.8 | AH27: 121.6 | AI27: 55.1 | AJ27: 66 | AK27: 57.3 | AL27: 67.8 | AM27: 45.8 | AN27: 40.7 | AO27: #N/A | AP27: 18.9 | AQ27: 80.9 | AR27: 47.7 | AS27: 43.8 | AT27: 28.1 | AU27: #N/A | AV27: 3.8 | AW27: 20.6 | AX27: 14 | AY27: #N/A | AZ27: #N/A | BA27: 33.8 | BB27: 74.1 | BC27: 69.5 | BD27: 103.4 | BE27: 77.1 | BF27: 165 | BG27: 116.3 | BH27: 85.4 | BI27: 63.3 | BJ27: 70.4 | BK27: 76.3 | BL27: 54.1 | BM27: 50.3 | BN27: 84.5 | BO27: 71.1 | BP27: 79.3 | BQ27: 97.2 | BR27: 89 | BS27: 82 | BT27: 58.1 | BU27: 74.3 | BV27: #N/A | BW27: #N/A | BX27: #N/A | BY27: 57.9 | BZ27: 68.3 | CA27: 59.6 | CB27: 38.8 | CC27: 79.1 | CD27: 117.7 | CE27: 98.9 | CF27: 53.3 | CG27: 94.3 | CH27: 73.9 | CI27: 17.5 | CJ27: 16.5 | CK27: 79.7 | CL27: 33.9 | CM27: 30.9 | CN27: 2.8 | CO27: 66.4 | CP27: 29.3 | CQ27: 51.3 | CR27: 58.4 | CS27: 109.6 | CT27: 250.6 | CU27: 18.1 | CV27: 75.3 | CW27: 47.5 | CX27: 70.1 | CY27: 8.7 | CZ27: #N/A | DA27: #N/A | DB27: #N/A | DC27: 21.4 | DD27: 134.7 | DE27: 25.2 | DF27: 27.1 | DG27: 95.1 | DH27: 46.1 | DI27: 37.1 | DJ27: 39 | DK27: 120 | DL27: 32.5 | DM27: 51.2 | DN27: 38.1 | DO27: 8.2 | DP27: 62.8 | DQ27: 14.9 | DR27: 24.1 | DS27: 16.3 | DT27: 233.4 | DU27: 19.8 | DV27: 23.3 | DW27: 2.8 | DX27: 11 | DY27: 6 | DZ27: 4.6 | EA27: 57.6 | EB27: 30.1 | EC27: 3.2 | ED27: 1.6 | EE27: 20.6 | EF27: 39.7 | EG27: #N/A | EH27: 6 | EI27: 5.8 | EJ27: 12.8 | EK27: 10.8 | EL27: 80 | EM27: 2.6 | EN27: 4.2 | EO27: 91.3 | EP27: 10.5 | EQ27: 20.7 | ER27: 15.8 | ES27: 30.3 | ET27: 6.6 | EU27: 10.2 | EV27: 23.9 | EW27: 22.4 | EX27: 34.1 | EY27: 15.8 | EZ27: 21.9 | FA27: 10 | FB27: 9 | FC27: 1 | FD27: 6.2 | FE27: #N/A | FF27: #N/A | FG27: 5.9 | FH27: 16.2 | FI27: 2.1 | FJ27: 11.6 | FK27: 11 | FL27: 6.2 | FM27: 33.4
A28: 1897 | B28: 63.5 | C28: 73.5 | D28: 60.7 | E28: 56.9 | F28: 47.7 | G28: 57.2 | H28: 89.9 | I28: 58.4 | J28: 69.4 | K28: 72.9 | L28: 50.6 | M28: 74.9 | N28: 62.6 | O28: #N/A | P28: 87 | Q28: 71.4 | R28: 112.1 | S28: 84.1 | T28: 71.5 | U28: #N/A | V28: 78.5 | W28: 74 | X28: 114.5 | Y28: #N/A | Z28: #N/A | AA28: 76.5 | AB28: 1114.2 | AC28: 189.7 | AD28: 1205.8 | AE28: 174.3 | AF28: 103.7 | AG28: 700 | AH28: 111 | AI28: 72.9 | AJ28: 62 | AK28: 58.3 | AL28: 73.1 | AM28: 47.8 | AN28: 48.5 | AO28: #N/A | AP28: 19 | AQ28: 83.5 | AR28: 57.7 | AS28: 46.4 | AT28: 30.3 | AU28: #N/A | AV28: 17.3 | AW28: 29.3 | AX28: 19.1 | AY28: #N/A | AZ28: #N/A | BA28: 37.1 | BB28: 76.4 | BC28: 73.2 | BD28: 76.5 | BE28: 85.7 | BF28: 110 | BG28: 100.7 | BH28: 102.2 | BI28: 63.6 | BJ28: 78.6 | BK28: 74.6 | BL28: 53.5 | BM28: 45.7 | BN28: 83 | BO28: 69.6 | BP28: 75.2 | BQ28: 89.5 | BR28: 91 | BS28: 79.7 | BT28: 55.2 | BU28: 77.3 | BV28: #N/A | BW28: #N/A | BX28: #N/A | BY28: 56.5 | BZ28: 68.6 | CA28: 67.1 | CB28: 39.8 | CC28: 84.4 | CD28: 110.1 | CE28: 94.7 | CF28: 40.8 | CG28: 112 | CH28: 94.6 | CI28: 17.3 | CJ28: 25.2 | CK28: 78.3 | CL28: 24.4 | CM28: 49.4 | CN28: 3.5 | CO28: 70.7 | CP28: 38 | CQ28: 61.4 | CR28: 64.5 | CS28: 266.7 | CT28: 257.3 | CU28: 35.9 | CV28: 85.7 | CW28: 49.7 | CX28: 69.7 | CY28: 4.7 | CZ28: #N/A | DA28: #N/A | DB28: #N/A | DC28: 28.2 | DD28: 112.3 | DE28: 34.6 | DF28: 31.2 | DG28: 64.6 | DH28: 30.4 | DI28: 39.5 | DJ28: 41.5 | DK28: 185.1 | DL28: 28.3 | DM28: 61.9 | DN28: 40.8 | DO28: 10.6 | DP28: 67.5 | DQ28: 19 | DR28: 22.8 | DS28: 16.3 | DT28: 212.9 | DU28: 18.5 | DV28: 27.7 | DW28: 4.5 | DX28: 11.2 | DY28: 5 | DZ28: 5.3 | EA28: 55 | EB28: 33.4 | EC28: 3.6 | ED28: 5.6 | EE28: 26.6 | EF28: 48.6 | EG28: #N/A | EH28: 6.5 | EI28: 6.2 | EJ28: 10.1 | EK28: 13.4 | EL28: 75.7 | EM28: 2.9 | EN28: 4.3 | EO28: 77.7 | EP28: 9.1 | EQ28: 33.2 | ER28: 21.8 | ES28: 31.5 | ET28: 8.4 | EU28: 11.1 | EV28: 25.9 | EW28: 53.4 | EX28: 33.2 | EY28: 28.9 | EZ28: 25.5 | FA28: 10.2 | FB28: 8.5 | FC28: 0.6 | FD28: 6.1 | FE28: #N/A | FF28: #N/A | FG28: 7.6 | FH28: 13.6 | FI28: 3.3 | FJ28: 13.7 | FK28: 7.9 | FL28: 4.5 | FM28: 34.1
A29: 1898 | B29: 65 | C29: 79 | D29: 64.5 | E29: 59.2 | F29: 52.9 | G29: 57.9 | H29: 91.6 | I29: 58.1 | J29: 76 | K29: 77.7 | L29: 43.2 | M29: 67.9 | N29: 61.4 | O29: #N/A | P29: 82.5 | Q29: 71.8 | R29: 110.4 | S29: 74.1 | T29: 74.5 | U29: #N/A | V29: 72.8 | W29: 70 | X29: 104.2 | Y29: #N/A | Z29: #N/A | AA29: 76.8 | AB29: 924.9 | AC29: 224.7 | AD29: 1156.4 | AE29: 207.4 | AF29: 122.4 | AG29: 425.3 | AH29: 133 | AI29: 96 | AJ29: 59.1 | AK29: 62.6 | AL29: 93.8 | AM29: 55.8 | AN29: 46.8 | AO29: #N/A | AP29: 22.3 | AQ29: 82.5 | AR29: 70.5 | AS29: 46.4 | AT29: 31.8 | AU29: #N/A | AV29: 19.5 | AW29: 42.3 | AX29: 27.6 | AY29: #N/A | AZ29: #N/A | BA29: 38.7 | BB29: 78.5 | BC29: 75.3 | BD29: 54.3 | BE29: 114 | BF29: 119.2 | BG29: 111.9 | BH29: 106.1 | BI29: 71.2 | BJ29: 89.7 | BK29: 75.3 | BL29: 49.5 | BM29: 65.5 | BN29: 83.8 | BO29: 67.9 | BP29: 73.6 | BQ29: 98.2 | BR29: 90.9 | BS29: 80.4 | BT29: 54.9 | BU29: 75.6 | BV29: #N/A | BW29: #N/A | BX29: #N/A | BY29: 59.2 | BZ29: 73.5 | CA29: 69.3 | CB29: 39.3 | CC29: 84.9 | CD29: 103.4 | CE29: 83.1 | CF29: 37.4 | CG29: 77.3 | CH29: 94.3 | CI29: 18.2 | CJ29: 23.8 | CK29: 69.4 | CL29: 22.3 | CM29: 52.9 | CN29: 3.7 | CO29: 63.6 | CP29: 34.4 | CQ29: 55.2 | CR29: 54.5 | CS29: 59.3 | CT29: 118.5 | CU29: 30.2 | CV29: 85.9 | CW29: 43.2 | CX29: 45.6 | CY29: 5.7 | CZ29: #N/A | DA29: #N/A | DB29: #N/A | DC29: 42.7 | DD29: 92.2 | DE29: 31.2 | DF29: 41.1 | DG29: 55.4 | DH29: 27.4 | DI29: 41.9 | DJ29: 35.3 | DK29: 235.5 | DL29: 28.8 | DM29: 76.8 | DN29: 53.4 | DO29: 6.5 | DP29: 82.5 | DQ29: 24.9 | DR29: 23.8 | DS29: 18.7 | DT29: 233.3 | DU29: 19.6 | DV29: 26.2 | DW29: 5.6 | DX29: 12.4 | DY29: 5 | DZ29: 6.4 | EA29: 48.4 | EB29: 36.4 | EC29: 3.5 | ED29: 5.8 | EE29: 36.2 | EF29: 63.9 | EG29: #N/A | EH29: 7.6 | EI29: 6.4 | EJ29: 9.5 | EK29: 9.5 | EL29: 53.7 | EM29: 4.1 | EN29: 4.4 | EO29: 76.5 | EP29: 8.6 | EQ29: 39.9 | ER29: 26.1 | ES29: 28.6 | ET29: 7.1 | EU29: 14.3 | EV29: 22.1 | EW29: 11.6 | EX29: 15 | EY29: 26.6 | EZ29: 25.5 | FA29: 9 | FB29: 5.5 | FC29: 0.7 | FD29: 6 | FE29: #N/A | FF29: #N/A | FG29: 12 | FH29: 12 | FI29: 4 | FJ29: 17.9 | FK29: 6.9 | FL29: 3.7 | FM29: 31.7
A30: 1899 | B30: 71.1 | C30: 74.9 | D30: 66.2 | E30: 59.9 | F30: 55.2 | G30: 63.2 | H30: 79.8 | I30: 60.1 | J30: 73.7 | K30: 78.4 | L30: 50.2 | M30: 68.3 | N30: 67 | O30: 126 | P30: 82 | Q30: 87.3 | R30: 121.4 | S30: 94.4 | T30: 105.6 | U30: #N/A | V30: 92.4 | W30: 77.1 | X30: 105.2 | Y30: 155 | Z30: 87.9 | AA30: 78.5 | AB30: 793.2 | AC30: 189.6 | AD30: 1382 | AE30: 198.6 | AF30: 116.5 | AG30: 543.1 | AH30: 151.5 | AI30: 106.7 | AJ30: 76.9 | AK30: 73.3 | AL30: 66.4 | AM30: 70.4 | AN30: 50.9 | AO30: 39.7 | AP30: 28.4 | AQ30: 80.8 | AR30: 77.1 | AS30: 45.2 | AT30: 26.9 | AU30: #N/A | AV30: 22 | AW30: 51.3 | AX30: 33.4 | AY30: 0.4 | AZ30: 57.2 | BA30: 49.6 | BB30: 77.5 | BC30: 67.8 | BD30: 52 | BE30: 108.3 | BF30: 119.2 | BG30: 121.2 | BH30: 108.7 | BI30: 72.6 | BJ30: 96.2 | BK30: 75.5 | BL30: 56.5 | BM30: 83.8 | BN30: 85 | BO30: 64.2 | BP30: 77.7 | BQ30: 112.8 | BR30: 100.3 | BS30: 84.5 | BT30: 57.2 | BU30: 92.5 | BV30: 129.2 | BW30: #N/A | BX30: 68.6 | BY30: 68.6 | BZ30: 77.8 | CA30: 84.1 | CB30: 66.9 | CC30: 99.6 | CD30: 100.1 | CE30: 87.5 | CF30: 46.5 | CG30: 98.3 | CH30: 103 | CI30: 24.6 | CJ30: 36 | CK30: 90.3 | CL30: 29.9 | CM30: 66.4 | CN30: 4.5 | CO30: 78.2 | CP30: 38.2 | CQ30: 55.8 | CR30: 59.1 | CS30: 63.1 | CT30: 108.3 | CU30: 42.3 | CV30: 85.8 | CW30: 37.1 | CX30: 73.2 | CY30: 8.4 | CZ30: 21.6 | DA30: #N/A | DB30: 56.3 | DC30: 64.8 | DD30: 95.9 | DE30: 42.5 | DF30: 44.4 | DG30: 60.7 | DH30: 35.4 | DI30: 45.2 | DJ30: 33.1 | DK30: 188.8 | DL30: 35.3 | DM30: 74.3 | DN30: 53.1 | DO30: 9.1 | DP30: 76.9 | DQ30: 28.6 | DR30: 30 | DS30: 22.1 | DT30: 191.8 | DU30: 24.5 | DV30: 31.1 | DW30: 5.6 | DX30: 15.7 | DY30: 6 | DZ30: 7.7 | EA30: 60.1 | EB30: 44 | EC30: 5 | ED30: 8.9 | EE30: 47.4 | EF30: 77.9 | EG30: 0.2 | EH30: 10.3 | EI30: 7.9 | EJ30: 10.6 | EK30: 10.9 | EL30: 56.1 | EM30: 5.2 | EN30: 6.6 | EO30: 107.9 | EP30: 11.8 | EQ30: 51.1 | ER30: 34.4 | ES30: 35.3 | ET30: 9 | EU30: 18.6 | EV30: 22.6 | EW30: 11.7 | EX30: 14.6 | EY30: 42.8 | EZ30: 25.3 | FA30: 8.1 | FB30: 9.3 | FC30: 1.2 | FD30: 7.2 | FE30: 0 | FF30: 5 | FG30: 16.1 | FH30: 13.2 | FI30: 6.6 | FJ30: 32.9 | FK30: 8.8 | FL30: 4.8 | FM30: 36
A31: 1900 | B31: 70.6 | C31: 75.4 | D31: 68.7 | E31: 65.2 | F31: 62.1 | G31: 66.9 | H31: 76.7 | I31: 72.5 | J31: 75 | K31: 79.5 | L31: 71.7 | M31: 90.6 | N31: 72.2 | O31: 123.4 | P31: 87.7 | Q31: 91.6 | R31: 150.4 | S31: 104.3 | T31: 103.3 | U31: #N/A | V31: 105.1 | W31: 99 | X31: 103.2 | Y31: 153.5 | Z31: 95.7 | AA31: 84.4 | AB31: 877.1 | AC31: 171.9 | AD31: 1421.7 | AE31: 178.1 | AF31: 108.3 | AG31: 522.9 | AH31: 155.6 | AI31: 99.4 | AJ31: 67.7 | AK31: 69.7 | AL31: 76.5 | AM31: 47.9 | AN31: 55.9 | AO31: 50.7 | AP31: 36.4 | AQ31: 94.9 | AR31: 66.6 | AS31: 45.7 | AT31: 37.2 | AU31: #N/A | AV31: 32.5 | AW31: 48.5 | AX31: 38.8 | AY31: 0.8 | AZ31: 58.9 | BA31: 48.6 | BB31: 81.3 | BC31: 66.3 | BD31: 61.7 | BE31: 112.7 | BF31: 137.5 | BG31: 121 | BH31: 100.3 | BI31: 77.2 | BJ31: 88.6 | BK31: 81.4 | BL31: 61.5 | BM31: 103.3 | BN31: 93.7 | BO31: 75.7 | BP31: 81.9 | BQ31: 120.7 | BR31: 97.9 | BS31: 88.3 | BT31: 67.2 | BU31: 98.1 | BV31: 124 | BW31: #N/A | BX31: 82.4 | BY31: 82.4 | BZ31: 82.2 | CA31: 95.5 | CB31: 75.2 | CC31: 117.4 | CD31: 107.7 | CE31: 93.5 | CF31: 40.5 | CG31: 108.3 | CH31: 92.2 | CI31: 29.1 | CJ31: 26.7 | CK31: 76.3 | CL31: 40.8 | CM31: 63.1 | CN31: 4.1 | CO31: 82.8 | CP31: 43 | CQ31: 53.9 | CR31: 58.4 | CS31: 88.2 | CT31: 111.3 | CU31: 29.4 | CV31: 92.3 | CW31: 41.4 | CX31: 59.1 | CY31: 14.8 | CZ31: 24.7 | DA31: #N/A | DB31: 35.5 | DC31: 41 | DD31: 101.7 | DE31: 63.1 | DF31: 45.2 | DG31: 65.6 | DH31: 36.2 | DI31: 47.1 | DJ31: 36.3 | DK31: 172.3 | DL31: 37.7 | DM31: 73.2 | DN31: 55.4 | DO31: 9.2 | DP31: 75.9 | DQ31: 32.2 | DR31: 26.9 | DS31: 21.3 | DT31: 315.9 | DU31: 19.7 | DV31: 36.8 | DW31: 7 | DX31: 21.5 | DY31: 7.3 | DZ31: 8.7 | EA31: 67.2 | EB31: 59.6 | EC31: 6.1 | ED31: 14.7 | EE31: 57.5 | EF31: 89 | EG31: 0.4 | EH31: 11.5 | EI31: 8.4 | EJ31: 9.7 | EK31: 11.8 | EL31: 59.5 | EM31: 6.5 | EN31: 5.6 | EO31: 91 | EP31: 14.9 | EQ31: 51.6 | ER31: 28.7 | ES31: 40.3 | ET31: 11 | EU31: 22.1 | EV31: 24.6 | EW31: 19.2 | EX31: 15.8 | EY31: 31.8 | EZ31: 26.6 | FA31: 9.4 | FB31: 8.8 | FC31: 2.3 | FD31: 7.9 | FE31: 0 | FF31: 3.8 | FG31: 12.2 | FH31: 14.8 | FI31: 11.2 | FJ31: 37.7 | FK31: 11.2 | FL31: 5.3 | FM31: 40.1
A32: 1901 | B32: 73.1 | C32: 77.9 | D32: 69.7 | E32: 70.7 | F32: 74.2 | G32: 64.7 | H32: 79.2 | I32: 75.2 | J32: 74.3 | K32: 72.9 | L32: 65.6 | M32: 76.4 | N32: 71.5 | O32: 103.4 | P32: 91.8 | Q32: 81.9 | R32: 151.5 | S32: 93.2 | T32: 103.4 | U32: #N/A | V32: 104.6 | W32: 96.5 | X32: 101.5 | Y32: 153.5 | Z32: 95.1 | AA32: 79.5 | AB32: 936.4 | AC32: 188.3 | AD32: 1508.7 | AE32: 179 | AF32: 109.6 | AG32: 517.8 | AH32: 156.1 | AI32: 105.9 | AJ32: 68.3 | AK32: 77.7 | AL32: 79.9 | AM32: 64.7 | AN32: 53.4 | AO32: 63 | AP32: 35.6 | AQ32: 87.2 | AR32: 64.3 | AS32: 50.8 | AT32: 21.3 | AU32: #N/A | AV32: 12.7 | AW32: 43.6 | AX32: 35.1 | AY32: 1.4 | AZ32: 59.6 | BA32: 50.2 | BB32: 71.8 | BC32: 69.6 | BD32: 53.3 | BE32: 105.5 | BF32: 126.7 | BG32: 104.8 | BH32: 93 | BI32: 79.4 | BJ32: 78 | BK32: 87.6 | BL32: 64.8 | BM32: 84.8 | BN32: 92.6 | BO32: 60.7 | BP32: 82.3 | BQ32: 100.2 | BR32: 93.1 | BS32: 85.4 | BT32: 74.8 | BU32: 96.1 | BV32: 126.8 | BW32: #N/A | BX32: 88 | BY32: 88 | BZ32: 90.5 | CA32: 105.5 | CB32: 74.3 | CC32: 99.4 | CD32: 111.9 | CE32: 93.9 | CF32: 46.1 | CG32: 76.6 | CH32: 125.7 | CI32: 32.4 | CJ32: 35.1 | CK32: 75.3 | CL32: 48 | CM32: 66.1 | CN32: 4.6 | CO32: 75.2 | CP32: 57.3 | CQ32: 61.9 | CR32: 61.3 | CS32: 80.2 | CT32: 109.3 | CU32: 43.9 | CV32: 97.6 | CW32: 44.5 | CX32: 63.6 | CY32: 10.7 | CZ32: 26.5 | DA32: #N/A | DB32: 58.8 | DC32: 65.3 | DD32: 1.01.1 | DE32: 107.2 | DF32: 46.2 | DG32: 77.9 | DH32: 38.7 | DI32: 50.5 | DJ32: 40.1 | DK32: 195.2 | DL32: 40.6 | DM32: 81.1 | DN32: 67.1 | DO32: 8.8 | DP32: 78.6 | DQ32: 35.6 | DR32: 26.9 | DS32: 21.8 | DT32: 301.9 | DU32: 25.2 | DV32: 34.8 | DW32: 7.3 | DX32: 22 | DY32: 6 | DZ32: 8 | EA32: 66.7 | EB32: 34.2 | EC32: 5.8 | ED32: 5.8 | EE32: 50.4 | EF32: 79 | EG32: 0.7 | EH32: 11.6 | EI32: 8.1 | EJ32: 9.7 | EK32: 8.7 | EL32: 70.2 | EM32: 6.7 | EN32: 6.8 | EO32: 77.8 | EP32: 16.2 | EQ32: 55.6 | ER32: 28.3 | ES32: 39.4 | ET32: 15.4 | EU32: 20.8 | EV32: 25.5 | EW32: 14 | EX32: 15.6 | EY32: 39.5 | EZ32: 26.8 | FA32: 9.8 | FB32: 10.5 | FC32: 1.6 | FD32: 8.6 | FE32: 0 | FF32: 6.6 | FG32: 20.8 | FH32: 16.2 | FI32: 21 | FJ32: 38.1 | FK32: 11.3 | FL32: 5.9 | FM32: 43.1
